Workbook
Name brand_all: Справочники!$CG$2:$CG$21
Name brand_esp: Справочники!$BN$2:$BN$3
Name brand_evn: Справочники!$BO$2:$BO$11
Name brand_npu: Справочники!$BP$2:$BP$2
Name brand_shgn: Справочники!$BM$2:$BM$7
Name brand_shvn: Справочники!$BX$2:$BX$2
Name cause_all: Справочники!$CJ$2:$CJ$146
Name cause_esp: Справочники!$AX$2:$AX$89
Name cause_npu: Справочники!$BY$2:$BY$2
Name cause_shgn: Справочники!$AY$2:$AY$57
Name comp: Справочники!$AZ$2:$AZ$23
Name condition: Справочники!$BQ$2:$BQ$5
Name confidence: Справочники!$BH$2:$BH$5
Name damage_all: Справочники!$CK$2:$CK$24
Name damage_esp: Справочники!$BB$2:$BB$21
Name damage_evn: Справочники!$CE$2:$CE$19
Name damage_npu: Справочники!$BE$2:$BE$13
Name damage_shgn: Справочники!$BC$2:$BC$16
Name damage_shvn: Справочники!$CD$2:$CD$15
Name damage_vin: Справочники!$BD$2:$BD$15
Name empty: Справочники!$BU$2:$BU$2
Name equip_cable: Справочники!$CN$2:$CN$6
Name equip_extension: Справочники!$CO$2:$CO$4
Name equip_hydro_maker: OFFSET(Справочники!$CP$2,0,0,6+MIN(COUNT(Справочники!$DJ$2:$DJ$1201),200),1)
Name equip_hydro_size: Справочники!$CQ$2:$CQ$13
Name equip_motor_maker: OFFSET(Справочники!$CL$2,0,0,2+MIN(COUNT(Справочники!$DI$2:$DI$1201),200),1)
Name equip_motor_size: Справочники!$CM$2:$CM$7
Name equip_nkt: Справочники!$CZ$2:$CZ$7
Name equip_pump_all: OFFSET(Справочники!$CY$2,0,0,17+MIN(COUNT(Справочники!$DH$2:$DH$1201),200),1)
Name equip_pump_esp: OFFSET(Справочники!$CU$2,0,0,7+MIN(COUNT(Справочники!$DD$2:$DD$1201),200),1)
Name equip_pump_evn: OFFSET(Справочники!$CV$2,0,0,4+MIN(COUNT(Справочники!$DE$2:$DE$1201),200),1)
Name equip_pump_npu: OFFSET(Справочники!$CW$2,0,0,2+MIN(COUNT(Справочники!$DG$2:$DG$1201),200),1)
Name equip_pump_shgn: OFFSET(Справочники!$CT$2,0,0,5+MIN(COUNT(Справочники!$DC$2:$DC$1201),200),1)
Name equip_pump_shvn: OFFSET(Справочники!$CX$2,0,0,3+MIN(COUNT(Справочники!$DF$2:$DF$1201),200),1)
Name equip_tms_maker: OFFSET(Справочники!$CR$2,0,0,5+MIN(COUNT(Справочники!$DK$2:$DK$1201),200),1)
Name equip_tms_size: Справочники!$CS$2:$CS$10
Name equip_years: OFFSET(Справочники!$DA$2,0,0,46+MIN(COUNT(Справочники!$DL$2:$DL$4801),100),1)
Name event: Справочники!$AO$2:$AO$8
Name fountain_depth_examples: Справочники!$DN$2:$DN$2
Name fountain_method: Справочники!$DM$2:$DM$2
Name method: Справочники!$BI$2:$BI$33
Name node_all: Справочники!$CI$2:$CI$32
Name node_esp: Справочники!$AT$2:$AT$22
Name node_evn: Справочники!$CC$2:$CC$19
Name node_npu: Справочники!$AW$2:$AW$10
Name node_shgn: Справочники!$AU$2:$AU$15
Name node_shvn: Справочники!$CB$2:$CB$13
Name node_vin: Справочники!$AV$2:$AV$12
Name nominal: Справочники!$BT$2:$BT$9
Name proof: Справочники!$BF$2:$BF$15
Name pump: Справочники!$AN$2:$AN$9
Name repair: Справочники!$BA$2:$BA$146
Name sign_all: Справочники!$CH$2:$CH$28
Name sign_esp: Справочники!$AP$2:$AP$21
Name sign_evn: Справочники!$CA$2:$CA$20
Name sign_npu: Справочники!$AS$2:$AS$10
Name sign_shgn: Справочники!$AQ$2:$AQ$14
Name sign_shvn: Справочники!$BZ$2:$BZ$10
Name sign_vin: Справочники!$AR$2:$AR$12
Name size_all: Справочники!$CF$2:$CF$14

Sheet Оперативный ввод
A1: РОСА — БЛАНК РЕЕСТРА ОТКАЗОВ · ОПЕРАТИВНЫЙ ВВОД
A2: Быстрый ввод события. Общие данные автоматически дублируются в подробный лист «История отказов». Подробную комплектацию и расширенное расследование дополняйте там.
A3: ОБЪЕКТ | C3: ЦИКЛ И ГНО | M3: ПРЕДВАРИТЕЛЬНАЯ ОЦЕНКА | S3: БЫСТРОЕ УТОЧНЕНИЕ | AA3: КОММЕНТАРИЙ | AB3: АВТОМАТИЧЕСКИ | AD3: ФОНТАННАЯ ДОБЫЧА
A4: Месторождение* | B4: № скважины* | C4: Дата пуска* | D4: Дата отказа / окончания* | E4: МРП, сут. (авто) | F4: Способ эксплуатации* | G4: Типоразмер ГНО 1* | H4: Типоразмер ГНО 2 (ОРД) | K4: Марка ГНО* | L4: Тип события* | M4: Признак / предпосылка* | N4: Отказавший узел* | O4: Предварительная причина* | P4: Основная категория осложнения* | Q4: Сопутствующее осложнение 1 | R4: Сопутствующее осложнение 2 | S4: ТКРС 1 | T4: ТКРС 2 | U4: Вид повреждения | V4: Итоговая причина | W4: Уточнённая категория осложнения | X4: Подтверждение | Y4: Статус расследования | Z4: Достоверность | AA4: Комментарий | AB4: Статус предварительного (авто) | AC4: Предварительное заключение (авто) | AD4: Тип насоса / способ эксплуатации | AE4: Глубина насоса, м
A5: Учебное значение заполнено для проверки шаблона | B5: 101 | C5: Учебное значение заполнено для проверки шаблона | D5: Учебное значение заполнено для проверки шаблона | E5: =IF(OR(C5="",D5=""),"",D5-C5) | F5: Учебное значение заполнено для проверки шаблона | G5: Учебное значение заполнено для проверки шаблона | H5: Учебное значение заполнено для проверки шаблона | K5: Учебное значение заполнено для проверки шаблона | L5: Учебное значение заполнено для проверки шаблона | M5: Учебное значение заполнено для проверки шаблона | N5: Учебное значение заполнено для проверки шаблона | O5: Учебное значение заполнено для проверки шаблона | P5: Учебное значение заполнено для проверки шаблона | Q5: Учебное значение заполнено для проверки шаблона | R5: Учебное значение заполнено для проверки шаблона | S5: Учебное значение заполнено для проверки шаблона | T5: Учебное значение заполнено для проверки шаблона | U5: Учебное значение заполнено для проверки шаблона | V5: Учебное значение заполнено для проверки шаблона | W5: Учебное значение заполнено для проверки шаблона | X5: Учебное значение заполнено для проверки шаблона | Y5: Учебное значение заполнено для проверки шаблона | Z5: Учебное значение заполнено для проверки шаблона | AA5: Учебное значение заполнено для проверки шаблона | AB5: =IF(AND(A5="",B5=""),"",IF(AND(A5<>"",B5<>"",C5<>"",D5<>"",F5<>"",G5<>"",K5<>"",ISERROR(SEARCH("по паспорту",G5)),ISERROR(SEARCH("по паспорту",K5)),L5<>"",M5<>"",N5<>"",O5<>"",P5<>""),"ГОТОВО","НЕ ГОТОВО")) | AC5: =IF(AB5<>"ГОТОВО","", "Предварительное заключение: "&A5&", скв. "&B5&". МРП: "&E5&" сут. ГНО: "&F5&", типоразмеры "&G5&IF(H5<>"",", "&H5,"")&IF(I5<>"",", "&I5,"")&IF(J5<>"",", "&J5,"")&", марка "&K5&". Событие: "&L5&". Признак: "&M5&". Узел: "&N5&". Предварительная причина: "&O5&". Основное осложнение: "&P5&IF(Q5<>"","; сопутствующее: "&Q5,"")&IF(R5<>"","; дополнительно: "&R5,"")&".") | AD5: Учебное значение заполнено для проверки шаблона | AE5: Учебное значение заполнено для проверки шаблона
A6: Учебное значение заполнено для проверки шаблона | B6: 101 | C6: Учебное значение заполнено для проверки шаблона | D6: Учебное значение заполнено для проверки шаблона | E6: =IF(OR(C6="",D6=""),"",D6-C6) | F6: Учебное значение заполнено для проверки шаблона | G6: Учебное значение заполнено для проверки шаблона | H6: Учебное значение заполнено для проверки шаблона | K6: Учебное значение заполнено для проверки шаблона | L6: Учебное значение заполнено для проверки шаблона | M6: Учебное значение заполнено для проверки шаблона | N6: Учебное значение заполнено для проверки шаблона | O6: Учебное значение заполнено для проверки шаблона | P6: Учебное значение заполнено для проверки шаблона | Q6: Учебное значение заполнено для проверки шаблона | R6: Учебное значение заполнено для проверки шаблона | S6: Учебное значение заполнено для проверки шаблона | T6: Учебное значение заполнено для проверки шаблона | U6: Учебное значение заполнено для проверки шаблона | V6: Учебное значение заполнено для проверки шаблона | W6: Учебное значение заполнено для проверки шаблона | X6: Учебное значение заполнено для проверки шаблона | Y6: Учебное значение заполнено для проверки шаблона | Z6: Учебное значение заполнено для проверки шаблона | AA6: Учебное значение заполнено для проверки шаблона | AB6: =IF(AND(A6="",B6=""),"",IF(AND(A6<>"",B6<>"",C6<>"",D6<>"",F6<>"",G6<>"",K6<>"",ISERROR(SEARCH("по паспорту",G6)),ISERROR(SEARCH("по паспорту",K6)),L6<>"",M6<>"",N6<>"",O6<>"",P6<>""),"ГОТОВО","НЕ ГОТОВО")) | AC6: =IF(AB6<>"ГОТОВО","", "Предварительное заключение: "&A6&", скв. "&B6&". МРП: "&E6&" сут. ГНО: "&F6&", типоразмеры "&G6&IF(H6<>"",", "&H6,"")&IF(I6<>"",", "&I6,"")&IF(J6<>"",", "&J6,"")&", марка "&K6&". Событие: "&L6&". Признак: "&M6&". Узел: "&N6&". Предварительная причина: "&O6&". Основное осложнение: "&P6&IF(Q6<>"","; сопутствующее: "&Q6,"")&IF(R6<>"","; дополнительно: "&R6,"")&".") | AD6: Учебное значение заполнено для проверки шаблона | AE6: Учебное значение заполнено для проверки шаблона
A7: Учебное значение заполнено для проверки шаблона | B7: 101 | C7: Учебное значение заполнено для проверки шаблона | D7: Учебное значение заполнено для проверки шаблона | E7: =IF(OR(C7="",D7=""),"",D7-C7) | F7: Учебное значение заполнено для проверки шаблона | G7: Учебное значение заполнено для проверки шаблона | H7: Учебное значение заполнено для проверки шаблона | K7: Учебное значение заполнено для проверки шаблона | L7: Учебное значение заполнено для проверки шаблона | M7: Учебное значение заполнено для проверки шаблона | N7: Учебное значение заполнено для проверки шаблона | O7: Учебное значение заполнено для проверки шаблона | P7: Учебное значение заполнено для проверки шаблона | Q7: Учебное значение заполнено для проверки шаблона | R7: Учебное значение заполнено для проверки шаблона | S7: Учебное значение заполнено для проверки шаблона | T7: Учебное значение заполнено для проверки шаблона | U7: Учебное значение заполнено для проверки шаблона | V7: Учебное значение заполнено для проверки шаблона | W7: Учебное значение заполнено для проверки шаблона | X7: Учебное значение заполнено для проверки шаблона | Y7: Учебное значение заполнено для проверки шаблона | Z7: Учебное значение заполнено для проверки шаблона | AA7: Учебное значение заполнено для проверки шаблона | AB7: =IF(AND(A7="",B7=""),"",IF(AND(A7<>"",B7<>"",C7<>"",D7<>"",F7<>"",G7<>"",K7<>"",ISERROR(SEARCH("по паспорту",G7)),ISERROR(SEARCH("по паспорту",K7)),L7<>"",M7<>"",N7<>"",O7<>"",P7<>""),"ГОТОВО","НЕ ГОТОВО")) | AC7: =IF(AB7<>"ГОТОВО","", "Предварительное заключение: "&A7&", скв. "&B7&". МРП: "&E7&" сут. ГНО: "&F7&", типоразмеры "&G7&IF(H7<>"",", "&H7,"")&IF(I7<>"",", "&I7,"")&IF(J7<>"",", "&J7,"")&", марка "&K7&". Событие: "&L7&". Признак: "&M7&". Узел: "&N7&". Предварительная причина: "&O7&". Основное осложнение: "&P7&IF(Q7<>"","; сопутствующее: "&Q7,"")&IF(R7<>"","; дополнительно: "&R7,"")&".") | AD7: Учебное значение заполнено для проверки шаблона | AE7: Учебное значение заполнено для проверки шаблона
A8: Учебное значение заполнено для проверки шаблона | B8: 102 | C8: Учебное значение заполнено для проверки шаблона | D8: Учебное значение заполнено для проверки шаблона | E8: =IF(OR(C8="",D8=""),"",D8-C8) | F8: Учебное значение заполнено для проверки шаблона | G8: Учебное значение заполнено для проверки шаблона | H8: Учебное значение заполнено для проверки шаблона | K8: Учебное значение заполнено для проверки шаблона | L8: Учебное значение заполнено для проверки шаблона | M8: Учебное значение заполнено для проверки шаблона | N8: Учебное значение заполнено для проверки шаблона | O8: Учебное значение заполнено для проверки шаблона | P8: Учебное значение заполнено для проверки шаблона | Q8: Учебное значение заполнено для проверки шаблона | R8: Учебное значение заполнено для проверки шаблона | S8: Учебное значение заполнено для проверки шаблона | T8: Учебное значение заполнено для проверки шаблона | U8: Учебное значение заполнено для проверки шаблона | V8: Учебное значение заполнено для проверки шаблона | W8: Учебное значение заполнено для проверки шаблона | X8: Учебное значение заполнено для проверки шаблона | Y8: Учебное значение заполнено для проверки шаблона | Z8: Учебное значение заполнено для проверки шаблона | AA8: Учебное значение заполнено для проверки шаблона | AB8: =IF(AND(A8="",B8=""),"",IF(AND(A8<>"",B8<>"",C8<>"",D8<>"",F8<>"",G8<>"",K8<>"",ISERROR(SEARCH("по паспорту",G8)),ISERROR(SEARCH("по паспорту",K8)),L8<>"",M8<>"",N8<>"",O8<>"",P8<>""),"ГОТОВО","НЕ ГОТОВО")) | AC8: =IF(AB8<>"ГОТОВО","", "Предварительное заключение: "&A8&", скв. "&B8&". МРП: "&E8&" сут. ГНО: "&F8&", типоразмеры "&G8&IF(H8<>"",", "&H8,"")&IF(I8<>"",", "&I8,"")&IF(J8<>"",", "&J8,"")&", марка "&K8&". Событие: "&L8&". Признак: "&M8&". Узел: "&N8&". Предварительная причина: "&O8&". Основное осложнение: "&P8&IF(Q8<>"","; сопутствующее: "&Q8,"")&IF(R8<>"","; дополнительно: "&R8,"")&".") | AD8: Учебное значение заполнено для проверки шаблона | AE8: Учебное значение заполнено для проверки шаблона
A9: Учебное значение заполнено для проверки шаблона | B9: 102 | C9: Учебное значение заполнено для проверки шаблона | D9: Учебное значение заполнено для проверки шаблона | E9: =IF(OR(C9="",D9=""),"",D9-C9) | F9: Учебное значение заполнено для проверки шаблона | G9: Учебное значение заполнено для проверки шаблона | H9: Учебное значение заполнено для проверки шаблона | K9: Учебное значение заполнено для проверки шаблона | L9: Учебное значение заполнено для проверки шаблона | M9: Учебное значение заполнено для проверки шаблона | N9: Учебное значение заполнено для проверки шаблона | O9: Учебное значение заполнено для проверки шаблона | P9: Учебное значение заполнено для проверки шаблона | Q9: Учебное значение заполнено для проверки шаблона | R9: Учебное значение заполнено для проверки шаблона | S9: Учебное значение заполнено для проверки шаблона | T9: Учебное значение заполнено для проверки шаблона | U9: Учебное значение заполнено для проверки шаблона | V9: Учебное значение заполнено для проверки шаблона | W9: Учебное значение заполнено для проверки шаблона | X9: Учебное значение заполнено для проверки шаблона | Y9: Учебное значение заполнено для проверки шаблона | Z9: Учебное значение заполнено для проверки шаблона | AA9: Учебное значение заполнено для проверки шаблона | AB9: =IF(AND(A9="",B9=""),"",IF(AND(A9<>"",B9<>"",C9<>"",D9<>"",F9<>"",G9<>"",K9<>"",ISERROR(SEARCH("по паспорту",G9)),ISERROR(SEARCH("по паспорту",K9)),L9<>"",M9<>"",N9<>"",O9<>"",P9<>""),"ГОТОВО","НЕ ГОТОВО")) | AC9: =IF(AB9<>"ГОТОВО","", "Предварительное заключение: "&A9&", скв. "&B9&". МРП: "&E9&" сут. ГНО: "&F9&", типоразмеры "&G9&IF(H9<>"",", "&H9,"")&IF(I9<>"",", "&I9,"")&IF(J9<>"",", "&J9,"")&", марка "&K9&". Событие: "&L9&". Признак: "&M9&". Узел: "&N9&". Предварительная причина: "&O9&". Основное осложнение: "&P9&IF(Q9<>"","; сопутствующее: "&Q9,"")&IF(R9<>"","; дополнительно: "&R9,"")&".") | AD9: Учебное значение заполнено для проверки шаблона | AE9: Учебное значение заполнено для проверки шаблона
A10: Учебное значение заполнено для проверки шаблона | B10: 102 | C10: Учебное значение заполнено для проверки шаблона | D10: Учебное значение заполнено для проверки шаблона | E10: =IF(OR(C10="",D10=""),"",D10-C10) | F10: Учебное значение заполнено для проверки шаблона | G10: Учебное значение заполнено для проверки шаблона | H10: Учебное значение заполнено для проверки шаблона | K10: Учебное значение заполнено для проверки шаблона | L10: Учебное значение заполнено для проверки шаблона | M10: Учебное значение заполнено для проверки шаблона | N10: Учебное значение заполнено для проверки шаблона | O10: Учебное значение заполнено для проверки шаблона | P10: Учебное значение заполнено для проверки шаблона | Q10: Учебное значение заполнено для проверки шаблона | R10: Учебное значение заполнено для проверки шаблона | S10: Учебное значение заполнено для проверки шаблона | T10: Учебное значение заполнено для проверки шаблона | U10: Учебное значение заполнено для проверки шаблона | V10: Учебное значение заполнено для проверки шаблона | W10: Учебное значение заполнено для проверки шаблона | X10: Учебное значение заполнено для проверки шаблона | Y10: Учебное значение заполнено для проверки шаблона | Z10: Учебное значение заполнено для проверки шаблона | AA10: Учебное значение заполнено для проверки шаблона | AB10: =IF(AND(A10="",B10=""),"",IF(AND(A10<>"",B10<>"",C10<>"",D10<>"",F10<>"",G10<>"",K10<>"",ISERROR(SEARCH("по паспорту",G10)),ISERROR(SEARCH("по паспорту",K10)),L10<>"",M10<>"",N10<>"",O10<>"",P10<>""),"ГОТОВО","НЕ ГОТОВО")) | AC10: =IF(AB10<>"ГОТОВО","", "Предварительное заключение: "&A10&", скв. "&B10&". МРП: "&E10&" сут. ГНО: "&F10&", типоразмеры "&G10&IF(H10<>"",", "&H10,"")&IF(I10<>"",", "&I10,"")&IF(J10<>"",", "&J10,"")&", марка "&K10&". Событие: "&L10&". Признак: "&M10&". Узел: "&N10&". Предварительная причина: "&O10&". Основное осложнение: "&P10&IF(Q10<>"","; сопутствующее: "&Q10,"")&IF(R10<>"","; дополнительно: "&R10,"")&".") | AD10: Учебное значение заполнено для проверки шаблона | AE10: Учебное значение заполнено для проверки шаблона
A11: Учебное значение заполнено для проверки шаблона | B11: 103 | C11: Учебное значение заполнено для проверки шаблона | D11: Учебное значение заполнено для проверки шаблона | E11: =IF(OR(C11="",D11=""),"",D11-C11) | F11: Учебное значение заполнено для проверки шаблона | G11: Учебное значение заполнено для проверки шаблона | H11: Учебное значение заполнено для проверки шаблона | K11: Учебное значение заполнено для проверки шаблона | L11: Учебное значение заполнено для проверки шаблона | M11: Учебное значение заполнено для проверки шаблона | N11: Учебное значение заполнено для проверки шаблона | O11: Учебное значение заполнено для проверки шаблона | P11: Учебное значение заполнено для проверки шаблона | Q11: Учебное значение заполнено для проверки шаблона | R11: Учебное значение заполнено для проверки шаблона | S11: Учебное значение заполнено для проверки шаблона | T11: Учебное значение заполнено для проверки шаблона | U11: Учебное значение заполнено для проверки шаблона | V11: Учебное значение заполнено для проверки шаблона | W11: Учебное значение заполнено для проверки шаблона | X11: Учебное значение заполнено для проверки шаблона | Y11: Учебное значение заполнено для проверки шаблона | Z11: Учебное значение заполнено для проверки шаблона | AA11: Учебное значение заполнено для проверки шаблона | AB11: =IF(AND(A11="",B11=""),"",IF(AND(A11<>"",B11<>"",C11<>"",D11<>"",F11<>"",G11<>"",K11<>"",ISERROR(SEARCH("по паспорту",G11)),ISERROR(SEARCH("по паспорту",K11)),L11<>"",M11<>"",N11<>"",O11<>"",P11<>""),"ГОТОВО","НЕ ГОТОВО")) | AC11: =IF(AB11<>"ГОТОВО","", "Предварительное заключение: "&A11&", скв. "&B11&". МРП: "&E11&" сут. ГНО: "&F11&", типоразмеры "&G11&IF(H11<>"",", "&H11,"")&IF(I11<>"",", "&I11,"")&IF(J11<>"",", "&J11,"")&", марка "&K11&". Событие: "&L11&". Признак: "&M11&". Узел: "&N11&". Предварительная причина: "&O11&". Основное осложнение: "&P11&IF(Q11<>"","; сопутствующее: "&Q11,"")&IF(R11<>"","; дополнительно: "&R11,"")&".") | AD11: Учебное значение заполнено для проверки шаблона | AE11: Учебное значение заполнено для проверки шаблона
A12: Учебное значение заполнено для проверки шаблона | B12: 103 | C12: Учебное значение заполнено для проверки шаблона | D12: Учебное значение заполнено для проверки шаблона | E12: =IF(OR(C12="",D12=""),"",D12-C12) | F12: Учебное значение заполнено для проверки шаблона | G12: Учебное значение заполнено для проверки шаблона | H12: Учебное значение заполнено для проверки шаблона | K12: Учебное значение заполнено для проверки шаблона | L12: Учебное значение заполнено для проверки шаблона | M12: Учебное значение заполнено для проверки шаблона | N12: Учебное значение заполнено для проверки шаблона | O12: Учебное значение заполнено для проверки шаблона | P12: Учебное значение заполнено для проверки шаблона | Q12: Учебное значение заполнено для проверки шаблона | R12: Учебное значение заполнено для проверки шаблона | S12: Учебное значение заполнено для проверки шаблона | T12: Учебное значение заполнено для проверки шаблона | U12: Учебное значение заполнено для проверки шаблона | V12: Учебное значение заполнено для проверки шаблона | W12: Учебное значение заполнено для проверки шаблона | X12: Учебное значение заполнено для проверки шаблона | Y12: Учебное значение заполнено для проверки шаблона | Z12: Учебное значение заполнено для проверки шаблона | AA12: Учебное значение заполнено для проверки шаблона | AB12: =IF(AND(A12="",B12=""),"",IF(AND(A12<>"",B12<>"",C12<>"",D12<>"",F12<>"",G12<>"",K12<>"",ISERROR(SEARCH("по паспорту",G12)),ISERROR(SEARCH("по паспорту",K12)),L12<>"",M12<>"",N12<>"",O12<>"",P12<>""),"ГОТОВО","НЕ ГОТОВО")) | AC12: =IF(AB12<>"ГОТОВО","", "Предварительное заключение: "&A12&", скв. "&B12&". МРП: "&E12&" сут. ГНО: "&F12&", типоразмеры "&G12&IF(H12<>"",", "&H12,"")&IF(I12<>"",", "&I12,"")&IF(J12<>"",", "&J12,"")&", марка "&K12&". Событие: "&L12&". Признак: "&M12&". Узел: "&N12&". Предварительная причина: "&O12&". Основное осложнение: "&P12&IF(Q12<>"","; сопутствующее: "&Q12,"")&IF(R12<>"","; дополнительно: "&R12,"")&".") | AD12: Учебное значение заполнено для проверки шаблона | AE12: Учебное значение заполнено для проверки шаблона
A13: Учебное значение заполнено для проверки шаблона | B13: 103 | C13: Учебное значение заполнено для проверки шаблона | D13: Учебное значение заполнено для проверки шаблона | E13: =IF(OR(C13="",D13=""),"",D13-C13) | F13: Учебное значение заполнено для проверки шаблона | G13: Учебное значение заполнено для проверки шаблона | H13: Учебное значение заполнено для проверки шаблона | K13: Учебное значение заполнено для проверки шаблона | L13: Учебное значение заполнено для проверки шаблона | M13: Учебное значение заполнено для проверки шаблона | N13: Учебное значение заполнено для проверки шаблона | O13: Учебное значение заполнено для проверки шаблона | P13: Учебное значение заполнено для проверки шаблона | Q13: Учебное значение заполнено для проверки шаблона | R13: Учебное значение заполнено для проверки шаблона | S13: Учебное значение заполнено для проверки шаблона | T13: Учебное значение заполнено для проверки шаблона | U13: Учебное значение заполнено для проверки шаблона | V13: Учебное значение заполнено для проверки шаблона | W13: Учебное значение заполнено для проверки шаблона | X13: Учебное значение заполнено для проверки шаблона | Y13: Учебное значение заполнено для проверки шаблона | Z13: Учебное значение заполнено для проверки шаблона | AA13: Учебное значение заполнено для проверки шаблона | AB13: =IF(AND(A13="",B13=""),"",IF(AND(A13<>"",B13<>"",C13<>"",D13<>"",F13<>"",G13<>"",K13<>"",ISERROR(SEARCH("по паспорту",G13)),ISERROR(SEARCH("по паспорту",K13)),L13<>"",M13<>"",N13<>"",O13<>"",P13<>""),"ГОТОВО","НЕ ГОТОВО")) | AC13: =IF(AB13<>"ГОТОВО","", "Предварительное заключение: "&A13&", скв. "&B13&". МРП: "&E13&" сут. ГНО: "&F13&", типоразмеры "&G13&IF(H13<>"",", "&H13,"")&IF(I13<>"",", "&I13,"")&IF(J13<>"",", "&J13,"")&", марка "&K13&". Событие: "&L13&". Признак: "&M13&". Узел: "&N13&". Предварительная причина: "&O13&". Основное осложнение: "&P13&IF(Q13<>"","; сопутствующее: "&Q13,"")&IF(R13<>"","; дополнительно: "&R13,"")&".") | AD13: Учебное значение заполнено для проверки шаблона | AE13: Учебное значение заполнено для проверки шаблона
A14: Учебное значение заполнено для проверки шаблона | B14: 104 | C14: Учебное значение заполнено для проверки шаблона | D14: Учебное значение заполнено для проверки шаблона | E14: =IF(OR(C14="",D14=""),"",D14-C14) | F14: Учебное значение заполнено для проверки шаблона | G14: Учебное значение заполнено для проверки шаблона | H14: Учебное значение заполнено для проверки шаблона | K14: Учебное значение заполнено для проверки шаблона | L14: Учебное значение заполнено для проверки шаблона | M14: Учебное значение заполнено для проверки шаблона | N14: Учебное значение заполнено для проверки шаблона | O14: Учебное значение заполнено для проверки шаблона | P14: Учебное значение заполнено для проверки шаблона | Q14: Учебное значение заполнено для проверки шаблона | R14: Учебное значение заполнено для проверки шаблона | S14: Учебное значение заполнено для проверки шаблона | T14: Учебное значение заполнено для проверки шаблона | U14: Учебное значение заполнено для проверки шаблона | V14: Учебное значение заполнено для проверки шаблона | W14: Учебное значение заполнено для проверки шаблона | X14: Учебное значение заполнено для проверки шаблона | Y14: Учебное значение заполнено для проверки шаблона | Z14: Учебное значение заполнено для проверки шаблона | AA14: Учебное значение заполнено для проверки шаблона | AB14: =IF(AND(A14="",B14=""),"",IF(AND(A14<>"",B14<>"",C14<>"",D14<>"",F14<>"",G14<>"",K14<>"",ISERROR(SEARCH("по паспорту",G14)),ISERROR(SEARCH("по паспорту",K14)),L14<>"",M14<>"",N14<>"",O14<>"",P14<>""),"ГОТОВО","НЕ ГОТОВО")) | AC14: =IF(AB14<>"ГОТОВО","", "Предварительное заключение: "&A14&", скв. "&B14&". МРП: "&E14&" сут. ГНО: "&F14&", типоразмеры "&G14&IF(H14<>"",", "&H14,"")&IF(I14<>"",", "&I14,"")&IF(J14<>"",", "&J14,"")&", марка "&K14&". Событие: "&L14&". Признак: "&M14&". Узел: "&N14&". Предварительная причина: "&O14&". Основное осложнение: "&P14&IF(Q14<>"","; сопутствующее: "&Q14,"")&IF(R14<>"","; дополнительно: "&R14,"")&".") | AD14: Учебное значение заполнено для проверки шаблона | AE14: Учебное значение заполнено для проверки шаблона
A15: Учебное значение заполнено для проверки шаблона | B15: 104 | C15: Учебное значение заполнено для проверки шаблона | D15: Учебное значение заполнено для проверки шаблона | E15: =IF(OR(C15="",D15=""),"",D15-C15) | F15: Учебное значение заполнено для проверки шаблона | G15: Учебное значение заполнено для проверки шаблона | H15: Учебное значение заполнено для проверки шаблона | K15: Учебное значение заполнено для проверки шаблона | L15: Учебное значение заполнено для проверки шаблона | M15: Учебное значение заполнено для проверки шаблона | N15: Учебное значение заполнено для проверки шаблона | O15: Учебное значение заполнено для проверки шаблона | P15: Учебное значение заполнено для проверки шаблона | Q15: Учебное значение заполнено для проверки шаблона | R15: Учебное значение заполнено для проверки шаблона | S15: Учебное значение заполнено для проверки шаблона | T15: Учебное значение заполнено для проверки шаблона | U15: Учебное значение заполнено для проверки шаблона | V15: Учебное значение заполнено для проверки шаблона | W15: Учебное значение заполнено для проверки шаблона | X15: Учебное значение заполнено для проверки шаблона | Y15: Учебное значение заполнено для проверки шаблона | Z15: Учебное значение заполнено для проверки шаблона | AA15: Учебное значение заполнено для проверки шаблона | AB15: =IF(AND(A15="",B15=""),"",IF(AND(A15<>"",B15<>"",C15<>"",D15<>"",F15<>"",G15<>"",K15<>"",ISERROR(SEARCH("по паспорту",G15)),ISERROR(SEARCH("по паспорту",K15)),L15<>"",M15<>"",N15<>"",O15<>"",P15<>""),"ГОТОВО","НЕ ГОТОВО")) | AC15: =IF(AB15<>"ГОТОВО","", "Предварительное заключение: "&A15&", скв. "&B15&". МРП: "&E15&" сут. ГНО: "&F15&", типоразмеры "&G15&IF(H15<>"",", "&H15,"")&IF(I15<>"",", "&I15,"")&IF(J15<>"",", "&J15,"")&", марка "&K15&". Событие: "&L15&". Признак: "&M15&". Узел: "&N15&". Предварительная причина: "&O15&". Основное осложнение: "&P15&IF(Q15<>"","; сопутствующее: "&Q15,"")&IF(R15<>"","; дополнительно: "&R15,"")&".") | AD15: Учебное значение заполнено для проверки шаблона | AE15: Учебное значение заполнено для проверки шаблона
A16: Учебное значение заполнено для проверки шаблона | B16: 104 | C16: Учебное значение заполнено для проверки шаблона | D16: Учебное значение заполнено для проверки шаблона | E16: =IF(OR(C16="",D16=""),"",D16-C16) | F16: Учебное значение заполнено для проверки шаблона | G16: Учебное значение заполнено для проверки шаблона | H16: Учебное значение заполнено для проверки шаблона | K16: Учебное значение заполнено для проверки шаблона | L16: Учебное значение заполнено для проверки шаблона | M16: Учебное значение заполнено для проверки шаблона | N16: Учебное значение заполнено для проверки шаблона | O16: Учебное значение заполнено для проверки шаблона | P16: Учебное значение заполнено для проверки шаблона | Q16: Учебное значение заполнено для проверки шаблона | R16: Учебное значение заполнено для проверки шаблона | S16: Учебное значение заполнено для проверки шаблона | T16: Учебное значение заполнено для проверки шаблона | U16: Учебное значение заполнено для проверки шаблона | V16: Учебное значение заполнено для проверки шаблона | W16: Учебное значение заполнено для проверки шаблона | X16: Учебное значение заполнено для проверки шаблона | Y16: Учебное значение заполнено для проверки шаблона | Z16: Учебное значение заполнено для проверки шаблона | AA16: Учебное значение заполнено для проверки шаблона | AB16: =IF(AND(A16="",B16=""),"",IF(AND(A16<>"",B16<>"",C16<>"",D16<>"",F16<>"",G16<>"",K16<>"",ISERROR(SEARCH("по паспорту",G16)),ISERROR(SEARCH("по паспорту",K16)),L16<>"",M16<>"",N16<>"",O16<>"",P16<>""),"ГОТОВО","НЕ ГОТОВО")) | AC16: =IF(AB16<>"ГОТОВО","", "Предварительное заключение: "&A16&", скв. "&B16&". МРП: "&E16&" сут. ГНО: "&F16&", типоразмеры "&G16&IF(H16<>"",", "&H16,"")&IF(I16<>"",", "&I16,"")&IF(J16<>"",", "&J16,"")&", марка "&K16&". Событие: "&L16&". Признак: "&M16&". Узел: "&N16&". Предварительная причина: "&O16&". Основное осложнение: "&P16&IF(Q16<>"","; сопутствующее: "&Q16,"")&IF(R16<>"","; дополнительно: "&R16,"")&".") | AD16: Учебное значение заполнено для проверки шаблона | AE16: Учебное значение заполнено для проверки шаблона
... A64: Учебное значение заполнено для проверки шаблона | B64: 120 | C64: Учебное значение заполнено для проверки шаблона | D64: Учебное значение заполнено для проверки шаблона | E64: =IF(OR(C64="",D64=""),"",D64-C64) | F64: Учебное значение заполнено для проверки шаблона | G64: Учебное значение заполнено для проверки шаблона | H64: Учебное значение заполнено для проверки шаблона | K64: Учебное значение заполнено для проверки шаблона | L64: Учебное значение заполнено для проверки шаблона | M64: Учебное значение заполнено для проверки шаблона | N64: Учебное значение заполнено для проверки шаблона | O64: Учебное значение заполнено для проверки шаблона | P64: Учебное значение заполнено для проверки шаблона | Q64: Учебное значение заполнено для проверки шаблона | R64: Учебное значение заполнено для проверки шаблона | S64: Учебное значение заполнено для проверки шаблона | T64: Учебное значение заполнено для проверки шаблона | U64: Учебное значение заполнено для проверки шаблона | V64: Учебное значение заполнено для проверки шаблона | W64: Учебное значение заполнено для проверки шаблона | X64: Учебное значение заполнено для проверки шаблона | Y64: Учебное значение заполнено для проверки шаблона | Z64: Учебное значение заполнено для проверки шаблона | AA64: Учебное значение заполнено для проверки шаблона | AB64: =IF(AND(A64="",B64=""),"",IF(AND(A64<>"",B64<>"",C64<>"",D64<>"",F64<>"",G64<>"",K64<>"",ISERROR(SEARCH("по паспорту",G64)),ISERROR(SEARCH("по паспорту",K64)),L64<>"",M64<>"",N64<>"",O64<>"",P64<>""),"ГОТОВО","НЕ ГОТОВО")) | AC64: =IF(AB64<>"ГОТОВО","", "Предварительное заключение: "&A64&", скв. "&B64&". МРП: "&E64&" сут. ГНО: "&F64&", типоразмеры "&G64&IF(H64<>"",", "&H64,"")&IF(I64<>"",", "&I64,"")&IF(J64<>"",", "&J64,"")&", марка "&K64&". Событие: "&L64&". Признак: "&M64&". Узел: "&N64&". Предварительная причина: "&O64&". Основное осложнение: "&P64&IF(Q64<>"","; сопутствующее: "&Q64,"")&IF(R64<>"","; дополнительно: "&R64,"")&".") | AD64: Учебное значение заполнено для проверки шаблона | AE64: Учебное значение заполнено для проверки шаблона
E65: =IF(OR(C65="",D65=""),"",D65-C65) | AB65: =IF(AND(A65="",B65=""),"",IF(AND(A65<>"",B65<>"",C65<>"",D65<>"",F65<>"",G65<>"",K65<>"",ISERROR(SEARCH("по паспорту",G65)),ISERROR(SEARCH("по паспорту",K65)),L65<>"",M65<>"",N65<>"",O65<>"",P65<>""),"ГОТОВО","НЕ ГОТОВО")) | AC65: =IF(AB65<>"ГОТОВО","", "Предварительное заключение: "&A65&", скв. "&B65&". МРП: "&E65&" сут. ГНО: "&F65&", типоразмеры "&G65&IF(H65<>"",", "&H65,"")&IF(I65<>"",", "&I65,"")&IF(J65<>"",", "&J65,"")&", марка "&K65&". Событие: "&L65&". Признак: "&M65&". Узел: "&N65&". Предварительная причина: "&O65&". Основное осложнение: "&P65&IF(Q65<>"","; сопутствующее: "&Q65,"")&IF(R65<>"","; дополнительно: "&R65,"")&".")
E66: =IF(OR(C66="",D66=""),"",D66-C66) | AB66: =IF(AND(A66="",B66=""),"",IF(AND(A66<>"",B66<>"",C66<>"",D66<>"",F66<>"",G66<>"",K66<>"",ISERROR(SEARCH("по паспорту",G66)),ISERROR(SEARCH("по паспорту",K66)),L66<>"",M66<>"",N66<>"",O66<>"",P66<>""),"ГОТОВО","НЕ ГОТОВО")) | AC66: =IF(AB66<>"ГОТОВО","", "Предварительное заключение: "&A66&", скв. "&B66&". МРП: "&E66&" сут. ГНО: "&F66&", типоразмеры "&G66&IF(H66<>"",", "&H66,"")&IF(I66<>"",", "&I66,"")&IF(J66<>"",", "&J66,"")&", марка "&K66&". Событие: "&L66&". Признак: "&M66&". Узел: "&N66&". Предварительная причина: "&O66&". Основное осложнение: "&P66&IF(Q66<>"","; сопутствующее: "&Q66,"")&IF(R66<>"","; дополнительно: "&R66,"")&".")
E67: =IF(OR(C67="",D67=""),"",D67-C67) | AB67: =IF(AND(A67="",B67=""),"",IF(AND(A67<>"",B67<>"",C67<>"",D67<>"",F67<>"",G67<>"",K67<>"",ISERROR(SEARCH("по паспорту",G67)),ISERROR(SEARCH("по паспорту",K67)),L67<>"",M67<>"",N67<>"",O67<>"",P67<>""),"ГОТОВО","НЕ ГОТОВО")) | AC67: =IF(AB67<>"ГОТОВО","", "Предварительное заключение: "&A67&", скв. "&B67&". МРП: "&E67&" сут. ГНО: "&F67&", типоразмеры "&G67&IF(H67<>"",", "&H67,"")&IF(I67<>"",", "&I67,"")&IF(J67<>"",", "&J67,"")&", марка "&K67&". Событие: "&L67&". Признак: "&M67&". Узел: "&N67&". Предварительная причина: "&O67&". Основное осложнение: "&P67&IF(Q67<>"","; сопутствующее: "&Q67,"")&IF(R67<>"","; дополнительно: "&R67,"")&".")
E68: =IF(OR(C68="",D68=""),"",D68-C68) | AB68: =IF(AND(A68="",B68=""),"",IF(AND(A68<>"",B68<>"",C68<>"",D68<>"",F68<>"",G68<>"",K68<>"",ISERROR(SEARCH("по паспорту",G68)),ISERROR(SEARCH("по паспорту",K68)),L68<>"",M68<>"",N68<>"",O68<>"",P68<>""),"ГОТОВО","НЕ ГОТОВО")) | AC68: =IF(AB68<>"ГОТОВО","", "Предварительное заключение: "&A68&", скв. "&B68&". МРП: "&E68&" сут. ГНО: "&F68&", типоразмеры "&G68&IF(H68<>"",", "&H68,"")&IF(I68<>"",", "&I68,"")&IF(J68<>"",", "&J68,"")&", марка "&K68&". Событие: "&L68&". Признак: "&M68&". Узел: "&N68&". Предварительная причина: "&O68&". Основное осложнение: "&P68&IF(Q68<>"","; сопутствующее: "&Q68,"")&IF(R68<>"","; дополнительно: "&R68,"")&".")
E69: =IF(OR(C69="",D69=""),"",D69-C69) | AB69: =IF(AND(A69="",B69=""),"",IF(AND(A69<>"",B69<>"",C69<>"",D69<>"",F69<>"",G69<>"",K69<>"",ISERROR(SEARCH("по паспорту",G69)),ISERROR(SEARCH("по паспорту",K69)),L69<>"",M69<>"",N69<>"",O69<>"",P69<>""),"ГОТОВО","НЕ ГОТОВО")) | AC69: =IF(AB69<>"ГОТОВО","", "Предварительное заключение: "&A69&", скв. "&B69&". МРП: "&E69&" сут. ГНО: "&F69&", типоразмеры "&G69&IF(H69<>"",", "&H69,"")&IF(I69<>"",", "&I69,"")&IF(J69<>"",", "&J69,"")&", марка "&K69&". Событие: "&L69&". Признак: "&M69&". Узел: "&N69&". Предварительная причина: "&O69&". Основное осложнение: "&P69&IF(Q69<>"","; сопутствующее: "&Q69,"")&IF(R69<>"","; дополнительно: "&R69,"")&".")
E70: =IF(OR(C70="",D70=""),"",D70-C70) | AB70: =IF(AND(A70="",B70=""),"",IF(AND(A70<>"",B70<>"",C70<>"",D70<>"",F70<>"",G70<>"",K70<>"",ISERROR(SEARCH("по паспорту",G70)),ISERROR(SEARCH("по паспорту",K70)),L70<>"",M70<>"",N70<>"",O70<>"",P70<>""),"ГОТОВО","НЕ ГОТОВО")) | AC70: =IF(AB70<>"ГОТОВО","", "Предварительное заключение: "&A70&", скв. "&B70&". МРП: "&E70&" сут. ГНО: "&F70&", типоразмеры "&G70&IF(H70<>"",", "&H70,"")&IF(I70<>"",", "&I70,"")&IF(J70<>"",", "&J70,"")&", марка "&K70&". Событие: "&L70&". Признак: "&M70&". Узел: "&N70&". Предварительная причина: "&O70&". Основное осложнение: "&P70&IF(Q70<>"","; сопутствующее: "&Q70,"")&IF(R70<>"","; дополнительно: "&R70,"")&".")
E71: =IF(OR(C71="",D71=""),"",D71-C71) | AB71: =IF(AND(A71="",B71=""),"",IF(AND(A71<>"",B71<>"",C71<>"",D71<>"",F71<>"",G71<>"",K71<>"",ISERROR(SEARCH("по паспорту",G71)),ISERROR(SEARCH("по паспорту",K71)),L71<>"",M71<>"",N71<>"",O71<>"",P71<>""),"ГОТОВО","НЕ ГОТОВО")) | AC71: =IF(AB71<>"ГОТОВО","", "Предварительное заключение: "&A71&", скв. "&B71&". МРП: "&E71&" сут. ГНО: "&F71&", типоразмеры "&G71&IF(H71<>"",", "&H71,"")&IF(I71<>"",", "&I71,"")&IF(J71<>"",", "&J71,"")&", марка "&K71&". Событие: "&L71&". Признак: "&M71&". Узел: "&N71&". Предварительная причина: "&O71&". Основное осложнение: "&P71&IF(Q71<>"","; сопутствующее: "&Q71,"")&IF(R71<>"","; дополнительно: "&R71,"")&".")
E72: =IF(OR(C72="",D72=""),"",D72-C72) | AB72: =IF(AND(A72="",B72=""),"",IF(AND(A72<>"",B72<>"",C72<>"",D72<>"",F72<>"",G72<>"",K72<>"",ISERROR(SEARCH("по паспорту",G72)),ISERROR(SEARCH("по паспорту",K72)),L72<>"",M72<>"",N72<>"",O72<>"",P72<>""),"ГОТОВО","НЕ ГОТОВО")) | AC72: =IF(AB72<>"ГОТОВО","", "Предварительное заключение: "&A72&", скв. "&B72&". МРП: "&E72&" сут. ГНО: "&F72&", типоразмеры "&G72&IF(H72<>"",", "&H72,"")&IF(I72<>"",", "&I72,"")&IF(J72<>"",", "&J72,"")&", марка "&K72&". Событие: "&L72&". Признак: "&M72&". Узел: "&N72&". Предварительная причина: "&O72&". Основное осложнение: "&P72&IF(Q72<>"","; сопутствующее: "&Q72,"")&IF(R72<>"","; дополнительно: "&R72,"")&".")
E73: =IF(OR(C73="",D73=""),"",D73-C73) | AB73: =IF(AND(A73="",B73=""),"",IF(AND(A73<>"",B73<>"",C73<>"",D73<>"",F73<>"",G73<>"",K73<>"",ISERROR(SEARCH("по паспорту",G73)),ISERROR(SEARCH("по паспорту",K73)),L73<>"",M73<>"",N73<>"",O73<>"",P73<>""),"ГОТОВО","НЕ ГОТОВО")) | AC73: =IF(AB73<>"ГОТОВО","", "Предварительное заключение: "&A73&", скв. "&B73&". МРП: "&E73&" сут. ГНО: "&F73&", типоразмеры "&G73&IF(H73<>"",", "&H73,"")&IF(I73<>"",", "&I73,"")&IF(J73<>"",", "&J73,"")&", марка "&K73&". Событие: "&L73&". Признак: "&M73&". Узел: "&N73&". Предварительная причина: "&O73&". Основное осложнение: "&P73&IF(Q73<>"","; сопутствующее: "&Q73,"")&IF(R73<>"","; дополнительно: "&R73,"")&".")
E74: =IF(OR(C74="",D74=""),"",D74-C74) | AB74: =IF(AND(A74="",B74=""),"",IF(AND(A74<>"",B74<>"",C74<>"",D74<>"",F74<>"",G74<>"",K74<>"",ISERROR(SEARCH("по паспорту",G74)),ISERROR(SEARCH("по паспорту",K74)),L74<>"",M74<>"",N74<>"",O74<>"",P74<>""),"ГОТОВО","НЕ ГОТОВО")) | AC74: =IF(AB74<>"ГОТОВО","", "Предварительное заключение: "&A74&", скв. "&B74&". МРП: "&E74&" сут. ГНО: "&F74&", типоразмеры "&G74&IF(H74<>"",", "&H74,"")&IF(I74<>"",", "&I74,"")&IF(J74<>"",", "&J74,"")&", марка "&K74&". Событие: "&L74&". Признак: "&M74&". Узел: "&N74&". Предварительная причина: "&O74&". Основное осложнение: "&P74&IF(Q74<>"","; сопутствующее: "&Q74,"")&IF(R74<>"","; дополнительно: "&R74,"")&".")
E75: =IF(OR(C75="",D75=""),"",D75-C75) | AB75: =IF(AND(A75="",B75=""),"",IF(AND(A75<>"",B75<>"",C75<>"",D75<>"",F75<>"",G75<>"",K75<>"",ISERROR(SEARCH("по паспорту",G75)),ISERROR(SEARCH("по паспорту",K75)),L75<>"",M75<>"",N75<>"",O75<>"",P75<>""),"ГОТОВО","НЕ ГОТОВО")) | AC75: =IF(AB75<>"ГОТОВО","", "Предварительное заключение: "&A75&", скв. "&B75&". МРП: "&E75&" сут. ГНО: "&F75&", типоразмеры "&G75&IF(H75<>"",", "&H75,"")&IF(I75<>"",", "&I75,"")&IF(J75<>"",", "&J75,"")&", марка "&K75&". Событие: "&L75&". Признак: "&M75&". Узел: "&N75&". Предварительная причина: "&O75&". Основное осложнение: "&P75&IF(Q75<>"","; сопутствующее: "&Q75,"")&IF(R75<>"","; дополнительно: "&R75,"")&".")
E76: =IF(OR(C76="",D76=""),"",D76-C76) | AB76: =IF(AND(A76="",B76=""),"",IF(AND(A76<>"",B76<>"",C76<>"",D76<>"",F76<>"",G76<>"",K76<>"",ISERROR(SEARCH("по паспорту",G76)),ISERROR(SEARCH("по паспорту",K76)),L76<>"",M76<>"",N76<>"",O76<>"",P76<>""),"ГОТОВО","НЕ ГОТОВО")) | AC76: =IF(AB76<>"ГОТОВО","", "Предварительное заключение: "&A76&", скв. "&B76&". МРП: "&E76&" сут. ГНО: "&F76&", типоразмеры "&G76&IF(H76<>"",", "&H76,"")&IF(I76<>"",", "&I76,"")&IF(J76<>"",", "&J76,"")&", марка "&K76&". Событие: "&L76&". Признак: "&M76&". Узел: "&N76&". Предварительная причина: "&O76&". Основное осложнение: "&P76&IF(Q76<>"","; сопутствующее: "&Q76,"")&IF(R76<>"","; дополнительно: "&R76,"")&".")
... E1204: =IF(OR(C1204="",D1204=""),"",D1204-C1204) | AB1204: =IF(AND(A1204="",B1204=""),"",IF(AND(A1204<>"",B1204<>"",C1204<>"",D1204<>"",F1204<>"",G1204<>"",K1204<>"",ISERROR(SEARCH("по паспорту",G1204)),ISERROR(SEARCH("по паспорту",K1204)),L1204<>"",M1204<>"",N1204<>"",O1204<>"",P1204<>""),"ГОТОВО","НЕ ГОТОВО")) | AC1204: =IF(AB1204<>"ГОТОВО","", "Предварительное заключение: "&A1204&", скв. "&B1204&". МРП: "&E1204&" сут. ГНО: "&F1204&", типоразмеры "&G1204&IF(H1204<>"",", "&H1204,"")&IF(I1204<>"",", "&I1204,"")&IF(J1204<>"",", "&J1204,"")&", марка "&K1204&". Событие: "&L1204&". Признак: "&M1204&". Узел: "&N1204&". Предварительная причина: "&O1204&". Основное осложнение: "&P1204&IF(Q1204<>"","; сопутствующее: "&Q1204,"")&IF(R1204<>"","; дополнительно: "&R1204,"")&".")

Sheet История отказов
A1: РОСА — БЛАНК РЕЕСТРА ОТКАЗОВ · ПОДРОБНАЯ ИСТОРИЯ
A2: Общие сведения автоматически дублируются с листа «Оперативный ввод». Фонтанная добыча и комплектация оборудования расположены до заключения комиссии. Для ШГН заполните отдельный блок «ШТАНГИ».
A3: ОБЪЕКТ | C3: ЦИКЛ И ГНО | M3: ПРЕДВАРИТЕЛЬНОЕ ЗАКЛЮЧЕНИЕ | U3: ПОЛНОЕ РАССЛЕДОВАНИЕ | AG3: ФОНТАННАЯ ДОБЫЧА | AI3: НАСОС | AK3: НКТ | AO3: ДВИГАТЕЛЬ | AS3: КАБЕЛЬ | AV3: УДЛИНИТЕЛЬ | AY3: ГИДРОЗАЩИТА | BC3: ТМС | BG3: ШТАНГИ | BN3: ЗАКЛЮЧЕНИЕ КОМИССИИ | BP3: ИТОГ | BR3: КОММЕНТАРИЙ
A4: Месторождение* | B4: № скважины* | C4: Дата пуска* | D4: Дата отказа / окончания* | E4: МРП, сут. (авто) | F4: Способ эксплуатации* | G4: Типоразмер ГНО 1* | H4: Типоразмер ГНО 2 (ОРД) | K4: Марка ГНО* | L4: Тип события* | M4: Признак / предпосылка* | N4: Отказавший узел* | O4: Предварительная причина* | P4: Основная категория осложнения* | Q4: Сопутствующее осложнение 1 | R4: Сопутствующее осложнение 2 | S4: Статус предварительного (авто) | T4: Предварительное заключение (авто) | U4: [ДОП] ТКРС 1 | V4: [ДОП] ТКРС 2 | W4: [ДОП] Вид повреждения | X4: [ДОП] Итоговая причина | Y4: [ДОП] Уточнённая категория осложнения | Z4: [ДОП] Метод до отказа 1 | AA4: [ДОП] Метод до отказа 2 | AB4: [ДОП] Метод после отказа 1 | AC4: [ДОП] Метод после отказа 2 | AD4: [ДОП] Подтверждение | AE4: [ДОП] Статус расследования | AF4: [ДОП] Достоверность | AG4: Тип насоса / способ эксплуатации | AH4: Глубина насоса, м | AI4: Условный диаметр / размер ШГН, мм | AJ4: Производитель насоса | AK4: Тип НКТ | AL4: Длина НКТ, м | AM4: Год НКТ | AN4: СПО НКТ | AO4: Состояние двигателя до спуска | AP4: Производитель двигателя | AQ4: Типоразмер двигателя (габарит), мм | AR4: Год двигателя | AS4: Состояние кабеля до спуска | AT4: Сечение кабеля, мм² | AU4: Длина кабеля, м | AV4: Состояние удлинителя до спуска | AW4: Сечение удлинителя, мм² | AX4: Длина удлинителя, м | AY4: Состояние гидрозащиты до спуска | AZ4: Производитель гидрозащиты | BA4: Типоразмер гидрозащиты (габарит), мм | BB4: Год гидрозащиты | BC4: Состояние ТМС до спуска | BD4: Производитель ТМС | BE4: Типоразмер ТМС | BF4: Год ТМС | BG4: Состояние штанг до спуска | BH4: Производитель штанг | BI4: Штанги Ø19 мм, м | BJ4: Штанги Ø22 мм, м | BK4: Штанги Ø25 мм, м | BL4: Год выпуска штанг | BM4: СПО штанг | BN4: [ДОП] Заключение комиссии / акт | BO4: [ДОП] Источник / документ | BP4: Статус полного (авто) | BQ4: Полное заключение (авто) | BR4: Комментарий
A5: Авиловское учебное | B5: 101 | C5: 01.11.2023 | D5: 01.02.2024 | E5: 92 | F5: УЭЦН | G5: УЭЦН · учебный типоразмер | H5: =IF('Оперативный ввод'!H5="","",'Оперативный ввод'!H5) | K5: Учебное исполнение 01 | L5: Отказ | M5: Карбонатный осадок; рост перепада давления | N5: Насос / НКТ | O5: Карбонатный осадок; рост перепада давления | P5: Солеотложения | R5: =IF('Оперативный ввод'!R5="","",'Оперативный ввод'!R5) | S5: =IF(AND(A5="",B5=""),"",IF(AND(A5<>"",B5<>"",C5<>"",D5<>"",F5<>"",G5<>"",K5<>"",ISERROR(SEARCH("по паспорту",G5)),ISERROR(SEARCH("по паспорту",K5)),L5<>"",M5<>"",N5<>"",O5<>"",P5<>""),"ГОТОВО","НЕ ГОТОВО")) | T5: =IF(S5<>"ГОТОВО","", "Предварительное заключение: "&A5&", скв. "&B5&". МРП: "&E5&" сут. ГНО: "&F5&", типоразмеры "&G5&IF(H5<>"",", "&H5,"")&IF(I5<>"",", "&I5,"")&IF(J5<>"",", "&J5,"")&", марка "&K5&". Событие: "&L5&". Признак: "&M5&". Узел: "&N5&". Предварительная причина: "&O5&". Основное осложнение: "&P5&IF(Q5<>"","; сопутствующее: "&Q5,"")&IF(R5<>"","; дополнительно: "&R5,"")&".") | U5: Учебное мероприятие №1 | V5: =IF('Оперативный ввод'!T5="","",'Оперативный ввод'!T5) | W5: Насос / НКТ | X5: Карбонатный осадок; рост перепада давления | Y5: С2 | Z5: Штатный режим / предыдущее мероприятие | AA5: Учебное значение заполнено для проверки полного шаблона | AB5: Повторная корректировка: Ингибитор солеотложений | AC5: Учебное значение заполнено для проверки полного шаблона | AD5: Лабораторный паспорт TRN-01-L1 | AE5: Учебный разбор заполнен | AF5: Синтетический учебный кейс | AG5: УЭЦН · учебный типоразмер | AH5: 1080 | AI5: Учебное значение | AJ5: Учебный изготовитель | AK5: Учебный НКТ | AL5: 1200 | AM5: 2021 | AN5: Учебная спуско-подъёмная операция | AO5: Учебное состояние | AP5: Учебный изготовитель | AQ5: Учебное исполнение | AR5: 2021 | AS5: Учебное состояние | AT5: 25 | AU5: 1110 | AV5: Учебное состояние | AW5: 16 | AX5: 1095 | AY5: Учебное состояние | AZ5: Учебный изготовитель | BA5: Учебное исполнение | BB5: 2021 | BC5: Учебное состояние | BD5: Учебный изготовитель | BE5: Учебное исполнение | BF5: 2021 | BG5: Учебное состояние | BH5: Учебный изготовитель | BI5: 240 | BJ5: 480 | BK5: 480 | BL5: 2021 | BM5: Учебная операция | BN5: Учебное заключение по событию 1; не производственный акт. | BO5: Учебный паспорт TRN-01-L1 | BP5: =IF(AND(A5="",B5=""),"",IF(AND(S5="ГОТОВО",U5<>"",W5<>"",X5<>"",AD5<>"",AE5<>"",AF5<>"",BN5<>"",BO5<>""),"ГОТОВО","НЕ ГОТОВО")) | BQ5: =IF(BP5<>"ГОТОВО","","Полное заключение: "&A5&", скв. "&B5&". МРП: "&E5&" сут. ГНО: "&F5&"; причина: "&X5&"; категория: "&Y5&"; решение комиссии: "&BN5&".") | BR5: TRN-01-F1; Повтор с корректировкой; Синтетическая учебная запись.
A6: Авиловское учебное | B6: 101 | C6: 05.02.2024 | D6: 12.07.2025 | E6: 523 | F6: УЭЦН | G6: УЭЦН · учебный типоразмер | H6: =IF('Оперативный ввод'!H6="","",'Оперативный ввод'!H6) | K6: Учебное исполнение 01 | L6: Отказ | M6: Рост КВЧ и абразивный износ | N6: Рабочая пара / фильтр | O6: Рост КВЧ и абразивный износ | P6: Механические примеси | Q6: Свободный газ | R6: =IF('Оперативный ввод'!R6="","",'Оперативный ввод'!R6) | S6: =IF(AND(A6="",B6=""),"",IF(AND(A6<>"",B6<>"",C6<>"",D6<>"",F6<>"",G6<>"",K6<>"",ISERROR(SEARCH("по паспорту",G6)),ISERROR(SEARCH("по паспорту",K6)),L6<>"",M6<>"",N6<>"",O6<>"",P6<>""),"ГОТОВО","НЕ ГОТОВО")) | T6: =IF(S6<>"ГОТОВО","", "Предварительное заключение: "&A6&", скв. "&B6&". МРП: "&E6&" сут. ГНО: "&F6&", типоразмеры "&G6&IF(H6<>"",", "&H6,"")&IF(I6<>"",", "&I6,"")&IF(J6<>"",", "&J6,"")&", марка "&K6&". Событие: "&L6&". Признак: "&M6&". Узел: "&N6&". Предварительная причина: "&O6&". Основное осложнение: "&P6&IF(Q6<>"","; сопутствующее: "&Q6,"")&IF(R6<>"","; дополнительно: "&R6,"")&".") | U6: Учебное мероприятие №2 | V6: =IF('Оперативный ввод'!T6="","",'Оперативный ввод'!T6) | W6: Рабочая пара / фильтр | X6: Рост КВЧ и абразивный износ | Y6: М2 | Z6: Штатный режим / предыдущее мероприятие | AA6: Учебное значение заполнено для проверки полного шаблона | AB6: Фильтрация и контроль фракций | AC6: Учебное значение заполнено для проверки полного шаблона | AD6: Лабораторный паспорт TRN-01-L2 | AE6: Учебный разбор заполнен | AF6: Синтетический учебный кейс | AG6: УЭЦН · учебный типоразмер | AH6: 1080 | AI6: Учебное значение | AJ6: Учебный изготовитель | AK6: Учебный НКТ | AL6: 1200 | AM6: 2022 | AN6: Учебная спуско-подъёмная операция | AO6: Учебное состояние | AP6: Учебный изготовитель | AQ6: Учебное исполнение | AR6: 2022 | AS6: Учебное состояние | AT6: 25 | AU6: 1110 | AV6: Учебное состояние | AW6: 16 | AX6: 1095 | AY6: Учебное состояние | AZ6: Учебный изготовитель | BA6: Учебное исполнение | BB6: 2022 | BC6: Учебное состояние | BD6: Учебный изготовитель | BE6: Учебное исполнение | BF6: 2022 | BG6: Учебное состояние | BH6: Учебный изготовитель | BI6: 240 | BJ6: 480 | BK6: 480 | BL6: 2022 | BM6: Учебная операция | BN6: Учебное заключение по событию 2; не производственный акт. | BO6: Учебный паспорт TRN-01-L2 | BP6: =IF(AND(A6="",B6=""),"",IF(AND(S6="ГОТОВО",U6<>"",W6<>"",X6<>"",AD6<>"",AE6<>"",AF6<>"",BN6<>"",BO6<>""),"ГОТОВО","НЕ ГОТОВО")) | BQ6: =IF(BP6<>"ГОТОВО","","Полное заключение: "&A6&", скв. "&B6&". МРП: "&E6&" сут. ГНО: "&F6&"; причина: "&X6&"; категория: "&Y6&"; решение комиссии: "&BN6&".") | BR6: TRN-01-F2; Новый подбор; Синтетическая учебная запись.
A7: Авиловское учебное | B7: 101 | C7: 17.07.2025 | D7: 23.02.2026 | E7: 221 | F7: УЭЦН | G7: УЭЦН · учебный типоразмер | H7: =IF('Оперативный ввод'!H7="","",'Оперативный ввод'!H7) | K7: Учебное исполнение 01 | L7: Отказ | M7: Микробиологический риск и рост железа | N7: НКТ / защитное покрытие | O7: Микробиологический риск и рост железа | P7: Биокоррозия | R7: =IF('Оперативный ввод'!R7="","",'Оперативный ввод'!R7) | S7: =IF(AND(A7="",B7=""),"",IF(AND(A7<>"",B7<>"",C7<>"",D7<>"",F7<>"",G7<>"",K7<>"",ISERROR(SEARCH("по паспорту",G7)),ISERROR(SEARCH("по паспорту",K7)),L7<>"",M7<>"",N7<>"",O7<>"",P7<>""),"ГОТОВО","НЕ ГОТОВО")) | T7: =IF(S7<>"ГОТОВО","", "Предварительное заключение: "&A7&", скв. "&B7&". МРП: "&E7&" сут. ГНО: "&F7&", типоразмеры "&G7&IF(H7<>"",", "&H7,"")&IF(I7<>"",", "&I7,"")&IF(J7<>"",", "&J7,"")&", марка "&K7&". Событие: "&L7&". Признак: "&M7&". Узел: "&N7&". Предварительная причина: "&O7&". Основное осложнение: "&P7&IF(Q7<>"","; сопутствующее: "&Q7,"")&IF(R7<>"","; дополнительно: "&R7,"")&".") | U7: Учебное мероприятие №3 | V7: =IF('Оперативный ввод'!T7="","",'Оперативный ввод'!T7) | W7: НКТ / защитное покрытие | X7: Микробиологический риск и рост железа | Y7: К1 | Z7: Штатный режим / предыдущее мероприятие | AA7: Учебное значение заполнено для проверки полного шаблона | AB7: Биоцидная обработка + контроль | AC7: Учебное значение заполнено для проверки полного шаблона | AD7: Лабораторный паспорт TRN-01-L3 | AE7: Учебный разбор заполнен | AF7: Синтетический учебный кейс | AG7: УЭЦН · учебный типоразмер | AH7: 1080 | AI7: Учебное значение | AJ7: Учебный изготовитель | AK7: Учебный НКТ | AL7: 1200 | AM7: 2023 | AN7: Учебная спуско-подъёмная операция | AO7: Учебное состояние | AP7: Учебный изготовитель | AQ7: Учебное исполнение | AR7: 2023 | AS7: Учебное состояние | AT7: 25 | AU7: 1110 | AV7: Учебное состояние | AW7: 16 | AX7: 1095 | AY7: Учебное состояние | AZ7: Учебный изготовитель | BA7: Учебное исполнение | BB7: 2023 | BC7: Учебное состояние | BD7: Учебный изготовитель | BE7: Учебное исполнение | BF7: 2023 | BG7: Учебное состояние | BH7: Учебный изготовитель | BI7: 240 | BJ7: 480 | BK7: 480 | BL7: 2023 | BM7: Учебная операция | BN7: Учебное заключение по событию 3; не производственный акт. | BO7: Учебный паспорт TRN-01-L3 | BP7: =IF(AND(A7="",B7=""),"",IF(AND(S7="ГОТОВО",U7<>"",W7<>"",X7<>"",AD7<>"",AE7<>"",AF7<>"",BN7<>"",BO7<>""),"ГОТОВО","НЕ ГОТОВО")) | BQ7: =IF(BP7<>"ГОТОВО","","Полное заключение: "&A7&", скв. "&B7&". МРП: "&E7&" сут. ГНО: "&F7&"; причина: "&X7&"; категория: "&Y7&"; решение комиссии: "&BN7&".") | BR7: TRN-01-F3; Новый подбор; Синтетическая учебная запись.
A8: Бешкульское учебное | B8: 102 | C8: 02.11.2023 | D8: 08.05.2024 | E8: 188 | F8: УШГН | G8: УШГН · учебный типоразмер | H8: =IF('Оперативный ввод'!H8="","",'Оперативный ввод'!H8) | K8: Учебное исполнение 02 | L8: Отказ | M8: Парафиновые отложения; падение подачи | N8: Приёмная часть насоса | O8: Парафиновые отложения; падение подачи | P8: АСПО | R8: =IF('Оперативный ввод'!R8="","",'Оперативный ввод'!R8) | S8: =IF(AND(A8="",B8=""),"",IF(AND(A8<>"",B8<>"",C8<>"",D8<>"",F8<>"",G8<>"",K8<>"",ISERROR(SEARCH("по паспорту",G8)),ISERROR(SEARCH("по паспорту",K8)),L8<>"",M8<>"",N8<>"",O8<>"",P8<>""),"ГОТОВО","НЕ ГОТОВО")) | T8: =IF(S8<>"ГОТОВО","", "Предварительное заключение: "&A8&", скв. "&B8&". МРП: "&E8&" сут. ГНО: "&F8&", типоразмеры "&G8&IF(H8<>"",", "&H8,"")&IF(I8<>"",", "&I8,"")&IF(J8<>"",", "&J8,"")&", марка "&K8&". Событие: "&L8&". Признак: "&M8&". Узел: "&N8&". Предварительная причина: "&O8&". Основное осложнение: "&P8&IF(Q8<>"","; сопутствующее: "&Q8,"")&IF(R8<>"","; дополнительно: "&R8,"")&".") | U8: Учебное мероприятие №1 | V8: =IF('Оперативный ввод'!T8="","",'Оперативный ввод'!T8) | W8: Приёмная часть насоса | X8: Парафиновые отложения; падение подачи | Y8: А2 | Z8: Штатный режим / предыдущее мероприятие | AA8: Учебное значение заполнено для проверки полного шаблона | AB8: Подбор растворителя и профилактики | AC8: Учебное значение заполнено для проверки полного шаблона | AD8: Лабораторный паспорт TRN-02-L1 | AE8: Учебный разбор заполнен | AF8: Синтетический учебный кейс | AG8: УШГН · учебный типоразмер | AH8: 1117 | AI8: Учебное значение | AJ8: Учебный изготовитель | AK8: Учебный НКТ | AL8: 1237 | AM8: 2021 | AN8: Учебная спуско-подъёмная операция | AO8: Учебное состояние | AP8: Учебный изготовитель | AQ8: Учебное исполнение | AR8: 2021 | AS8: Учебное состояние | AT8: 25 | AU8: 1147 | AV8: Учебное состояние | AW8: 16 | AX8: 1132 | AY8: Учебное состояние | AZ8: Учебный изготовитель | BA8: Учебное исполнение | BB8: 2021 | BC8: Учебное состояние | BD8: Учебный изготовитель | BE8: Учебное исполнение | BF8: 2021 | BG8: Учебное состояние | BH8: Учебный изготовитель | BI8: 247 | BJ8: 494 | BK8: 494 | BL8: 2021 | BM8: Учебная операция | BN8: Учебное заключение по событию 1; не производственный акт. | BO8: Учебный паспорт TRN-02-L1 | BP8: =IF(AND(A8="",B8=""),"",IF(AND(S8="ГОТОВО",U8<>"",W8<>"",X8<>"",AD8<>"",AE8<>"",AF8<>"",BN8<>"",BO8<>""),"ГОТОВО","НЕ ГОТОВО")) | BQ8: =IF(BP8<>"ГОТОВО","","Полное заключение: "&A8&", скв. "&B8&". МРП: "&E8&" сут. ГНО: "&F8&"; причина: "&X8&"; категория: "&Y8&"; решение комиссии: "&BN8&".") | BR8: TRN-02-F1; Новый подбор; Синтетическая учебная запись.
A9: Бешкульское учебное | B9: 102 | C9: 13.05.2024 | D9: 19.10.2025 | E9: 524 | F9: УШГН | G9: УШГН · учебный типоразмер | H9: =IF('Оперативный ввод'!H9="","",'Оперативный ввод'!H9) | K9: Учебное исполнение 02 | L9: Отказ | M9: Рост вязкости и замедленное водоотделение | N9: Насос / выкидная линия | O9: Рост вязкости и замедленное водоотделение | P9: Высокая вязкость / эмульсия | Q9: Высокая вязкость / эмульсия | R9: =IF('Оперативный ввод'!R9="","",'Оперативный ввод'!R9) | S9: =IF(AND(A9="",B9=""),"",IF(AND(A9<>"",B9<>"",C9<>"",D9<>"",F9<>"",G9<>"",K9<>"",ISERROR(SEARCH("по паспорту",G9)),ISERROR(SEARCH("по паспорту",K9)),L9<>"",M9<>"",N9<>"",O9<>"",P9<>""),"ГОТОВО","НЕ ГОТОВО")) | T9: =IF(S9<>"ГОТОВО","", "Предварительное заключение: "&A9&", скв. "&B9&". МРП: "&E9&" сут. ГНО: "&F9&", типоразмеры "&G9&IF(H9<>"",", "&H9,"")&IF(I9<>"",", "&I9,"")&IF(J9<>"",", "&J9,"")&", марка "&K9&". Событие: "&L9&". Признак: "&M9&". Узел: "&N9&". Предварительная причина: "&O9&". Основное осложнение: "&P9&IF(Q9<>"","; сопутствующее: "&Q9,"")&IF(R9<>"","; дополнительно: "&R9,"")&".") | U9: Учебное мероприятие №2 | V9: =IF('Оперативный ввод'!T9="","",'Оперативный ввод'!T9) | W9: Насос / выкидная линия | X9: Рост вязкости и замедленное водоотделение | Y9: В2 | Z9: Штатный режим / предыдущее мероприятие | AA9: Учебное значение заполнено для проверки полного шаблона | AB9: Подбор деэмульгатора | AC9: Учебное значение заполнено для проверки полного шаблона | AD9: Лабораторный паспорт TRN-02-L2 | AE9: Учебный разбор заполнен | AF9: Синтетический учебный кейс | AG9: УШГН · учебный типоразмер | AH9: 1117 | AI9: Учебное значение | AJ9: Учебный изготовитель | AK9: Учебный НКТ | AL9: 1237 | AM9: 2022 | AN9: Учебная спуско-подъёмная операция | AO9: Учебное состояние | AP9: Учебный изготовитель | AQ9: Учебное исполнение | AR9: 2022 | AS9: Учебное состояние | AT9: 25 | AU9: 1147 | AV9: Учебное состояние | AW9: 16 | AX9: 1132 | AY9: Учебное состояние | AZ9: Учебный изготовитель | BA9: Учебное исполнение | BB9: 2022 | BC9: Учебное состояние | BD9: Учебный изготовитель | BE9: Учебное исполнение | BF9: 2022 | BG9: Учебное состояние | BH9: Учебный изготовитель | BI9: 247 | BJ9: 494 | BK9: 494 | BL9: 2022 | BM9: Учебная операция | BN9: Учебное заключение по событию 2; не производственный акт. | BO9: Учебный паспорт TRN-02-L2 | BP9: =IF(AND(A9="",B9=""),"",IF(AND(S9="ГОТОВО",U9<>"",W9<>"",X9<>"",AD9<>"",AE9<>"",AF9<>"",BN9<>"",BO9<>""),"ГОТОВО","НЕ ГОТОВО")) | BQ9: =IF(BP9<>"ГОТОВО","","Полное заключение: "&A9&", скв. "&B9&". МРП: "&E9&" сут. ГНО: "&F9&"; причина: "&X9&"; категория: "&Y9&"; решение комиссии: "&BN9&".") | BR9: TRN-02-F2; Новый подбор; Синтетическая учебная запись.
A10: Бешкульское учебное | B10: 102 | C10: 25.10.2025 | D10: 04.05.2026 | E10: 191 | F10: УШГН | G10: УШГН · учебный типоразмер | H10: =IF('Оперативный ввод'!H10="","",'Оперативный ввод'!H10) | K10: Учебное исполнение 02 | L10: Отказ | M10: Карбонатный осадок; рост перепада давления | N10: Насос / НКТ | O10: Карбонатный осадок; рост перепада давления | P10: Солеотложения | R10: =IF('Оперативный ввод'!R10="","",'Оперативный ввод'!R10) | S10: =IF(AND(A10="",B10=""),"",IF(AND(A10<>"",B10<>"",C10<>"",D10<>"",F10<>"",G10<>"",K10<>"",ISERROR(SEARCH("по паспорту",G10)),ISERROR(SEARCH("по паспорту",K10)),L10<>"",M10<>"",N10<>"",O10<>"",P10<>""),"ГОТОВО","НЕ ГОТОВО")) | T10: =IF(S10<>"ГОТОВО","", "Предварительное заключение: "&A10&", скв. "&B10&". МРП: "&E10&" сут. ГНО: "&F10&", типоразмеры "&G10&IF(H10<>"",", "&H10,"")&IF(I10<>"",", "&I10,"")&IF(J10<>"",", "&J10,"")&", марка "&K10&". Событие: "&L10&". Признак: "&M10&". Узел: "&N10&". Предварительная причина: "&O10&". Основное осложнение: "&P10&IF(Q10<>"","; сопутствующее: "&Q10,"")&IF(R10<>"","; дополнительно: "&R10,"")&".") | U10: Учебное мероприятие №3 | V10: =IF('Оперативный ввод'!T10="","",'Оперативный ввод'!T10) | W10: Насос / НКТ | X10: Карбонатный осадок; рост перепада давления | Y10: С2 | Z10: Штатный режим / предыдущее мероприятие | AA10: Учебное значение заполнено для проверки полного шаблона | AB10: Повторная корректировка: Ингибитор солеотложений | AC10: Учебное значение заполнено для проверки полного шаблона | AD10: Лабораторный паспорт TRN-02-L3 | AE10: Учебный разбор заполнен | AF10: Синтетический учебный кейс | AG10: УШГН · учебный типоразмер | AH10: 1117 | AI10: Учебное значение | AJ10: Учебный изготовитель | AK10: Учебный НКТ | AL10: 1237 | AM10: 2023 | AN10: Учебная спуско-подъёмная операция | AO10: Учебное состояние | AP10: Учебный изготовитель | AQ10: Учебное исполнение | AR10: 2023 | AS10: Учебное состояние | AT10: 25 | AU10: 1147 | AV10: Учебное состояние | AW10: 16 | AX10: 1132 | AY10: Учебное состояние | AZ10: Учебный изготовитель | BA10: Учебное исполнение | BB10: 2023 | BC10: Учебное состояние | BD10: Учебный изготовитель | BE10: Учебное исполнение | BF10: 2023 | BG10: Учебное состояние | BH10: Учебный изготовитель | BI10: 247 | BJ10: 494 | BK10: 494 | BL10: 2023 | BM10: Учебная операция | BN10: Учебное заключение по событию 3; не производственный акт. | BO10: Учебный паспорт TRN-02-L3 | BP10: =IF(AND(A10="",B10=""),"",IF(AND(S10="ГОТОВО",U10<>"",W10<>"",X10<>"",AD10<>"",AE10<>"",AF10<>"",BN10<>"",BO10<>""),"ГОТОВО","НЕ ГОТОВО")) | BQ10: =IF(BP10<>"ГОТОВО","","Полное заключение: "&A10&", скв. "&B10&". МРП: "&E10&" сут. ГНО: "&F10&"; причина: "&X10&"; категория: "&Y10&"; решение комиссии: "&BN10&".") | BR10: TRN-02-F3; Повтор с корректировкой; Синтетическая учебная запись.
