Workbook
Name pump: 'Справочники'!$AN$2:$AN$6
Name event: 'Справочники'!$AO$2:$AO$8
Name sign_esp: 'Справочники'!$AP$2:$AP$21
Name sign_shgn: 'Справочники'!$AQ$2:$AQ$14
Name sign_vin: 'Справочники'!$AR$2:$AR$12
Name sign_npu: 'Справочники'!$AS$2:$AS$10
Name node_esp: 'Справочники'!$AT$2:$AT$22
Name node_shgn: 'Справочники'!$AU$2:$AU$15
Name node_vin: 'Справочники'!$AV$2:$AV$12
Name node_npu: 'Справочники'!$AW$2:$AW$10
Name cause_esp: 'Справочники'!$AX$2:$AX$89
Name cause_shgn: 'Справочники'!$AY$2:$AY$57
Name comp: 'Справочники'!$AZ$2:$AZ$23
Name repair: 'Справочники'!$BA$2:$BA$146
Name damage_esp: 'Справочники'!$BB$2:$BB$21
Name damage_shgn: 'Справочники'!$BC$2:$BC$16
Name damage_vin: 'Справочники'!$BD$2:$BD$15
Name damage_npu: 'Справочники'!$BE$2:$BE$13
Name proof: 'Справочники'!$BF$2:$BF$15
Name status: 'Справочники'!$BG$2:$BG$7
Name confidence: 'Справочники'!$BH$2:$BH$5
Name method: 'Справочники'!$BI$2:$BI$33
Name size_shgn: 'Справочники'!$BJ$2:$BJ$7
Name size_esp: 'Справочники'!$BK$2:$BK$4
Name size_evn: 'Справочники'!$BL$2:$BL$2
Name brand_shgn: 'Справочники'!$BM$2:$BM$7
Name brand_esp: 'Справочники'!$BN$2:$BN$3
Name brand_evn: 'Справочники'!$BO$2:$BO$11
Name brand_npu: 'Справочники'!$BP$2:$BP$2
Name condition: 'Справочники'!$BQ$2:$BQ$5
Name tubing: 'Справочники'!$BR$2:$BR$5
Name workover: 'Справочники'!$BS$2:$BS$5
Name nominal: 'Справочники'!$BT$2:$BT$7
Name empty: 'Справочники'!$BU$2:$BU$2
Name size_shvn: 'Справочники'!$BV$2:$BV$2
Name size_npu: 'Справочники'!$BW$2:$BW$2
Name brand_shvn: 'Справочники'!$BX$2:$BX$2
Name cause_npu: 'Справочники'!$BY$2:$BY$2
Name sign_shvn: 'Справочники'!$BZ$2:$BZ$10
Name sign_evn: 'Справочники'!$CA$2:$CA$20
Name node_shvn: 'Справочники'!$CB$2:$CB$13
Name node_evn: 'Справочники'!$CC$2:$CC$19
Name damage_shvn: 'Справочники'!$CD$2:$CD$15
Name damage_evn: 'Справочники'!$CE$2:$CE$19
Name size_all: 'Справочники'!$CF$2:$CF$13
Name brand_all: 'Справочники'!$CG$2:$CG$21
Name sign_all: 'Справочники'!$CH$2:$CH$28
Name node_all: 'Справочники'!$CI$2:$CI$32
Name cause_all: 'Справочники'!$CJ$2:$CJ$146
Name damage_all: 'Справочники'!$CK$2:$CK$24
Name equip_motor_maker: OFFSET('Справочники'!$CL$2,0,0,2+MIN(COUNT('Справочники'!$DI$2:$DI$1201),200),1)
Name equip_motor_size: 'Справочники'!$CM$2:$CM$7
Name equip_cable: 'Справочники'!$CN$2:$CN$6
Name equip_extension: 'Справочники'!$CO$2:$CO$4
Name equip_hydro_maker: OFFSET('Справочники'!$CP$2,0,0,2+MIN(COUNT('Справочники'!$DJ$2:$DJ$1201),200),1)
Name equip_hydro_size: 'Справочники'!$CQ$2:$CQ$9
Name equip_tms_maker: OFFSET('Справочники'!$CR$2,0,0,1+MIN(COUNT('Справочники'!$DK$2:$DK$1201),200),1)
Name equip_tms_size: 'Справочники'!$CS$2:$CS$6
Name equip_pump_shgn: OFFSET('Справочники'!$CT$2,0,0,1+MIN(COUNT('Справочники'!$DC$2:$DC$1201),200),1)
Name equip_pump_esp: OFFSET('Справочники'!$CU$2,0,0,2+MIN(COUNT('Справочники'!$DD$2:$DD$1201),200),1)

Sheet Оперативный ввод
A1: РОСА — ОПЕРАТИВНОЕ ВНЕСЕНИЕ ДАННЫХ ПО ОТКАЗАМ
A2: Быстрый ввод события. Общие данные автоматически дублируются в подробный лист «История отказов». Подробную комплектацию и расширенное расследование дополняйте там.
A3: ОБЪЕКТ | C3: ЦИКЛ И ГНО | J3: ПРЕДВАРИТЕЛЬНАЯ ОЦЕНКА | P3: БЫСТРОЕ УТОЧНЕНИЕ | X3: КОММЕНТАРИЙ | Y3: АВТОМАТИЧЕСКИ
A4: Месторождение* | B4: № скважины* | C4: Дата пуска* | D4: Дата отказа / окончания* | E4: МРП, сут. (авто) | F4: Способ эксплуатации* | G4: Типоразмер ГНО* | H4: Марка ГНО* | I4: Тип события* | J4: Признак / предпосылка* | K4: Отказавший узел* | L4: Предварительная причина* | M4: Основная категория осложнения* | N4: Сопутствующее осложнение 1 | O4: Сопутствующее осложнение 2 | P4: ТКРС 1 | Q4: ТКРС 2 | R4: Вид повреждения | S4: Итоговая причина | T4: Уточнённая категория осложнения | U4: Подтверждение | V4: Статус расследования | W4: Достоверность | X4: Комментарий | Y4: Статус предварительного (авто) | Z4: Предварительное заключение (авто)
E5: =IF(OR(C5="",D5=""),"",D5-C5) | Y5: =IF(AND(A5="",B5=""),"",IF(AND(A5<>"",B5<>"",C5<>"",D5<>"",F5<>"",G5<>"",H5<>"",ISERROR(SEARCH("по паспорту",G5)),ISERROR(SEARCH("по паспорту",H5)),I5<>"",J5<>"",K5<>"",L5<>"",M5<>""),"ГОТОВО","НЕ ГОТОВО")) | Z5: =IF(Y5<>"ГОТОВО","", "Предварительное заключение: "&A5&", скв. "&B5&". МРП: "&E5&" сут. ГНО: "&F5&", типоразмер "&G5&", марка "&H5&". Событие: "&I5&". Признак: "&J5&". Узел: "&K5&". Предварительная причина: "&L5&". Основное осложнение: "&M5&IF(N5<>"","; сопутствующее: "&N5,"")&IF(O5<>"","; дополнительно: "&O5,"")&".")
E6: =IF(OR(C6="",D6=""),"",D6-C6) | Y6: =IF(AND(A6="",B6=""),"",IF(AND(A6<>"",B6<>"",C6<>"",D6<>"",F6<>"",G6<>"",H6<>"",ISERROR(SEARCH("по паспорту",G6)),ISERROR(SEARCH("по паспорту",H6)),I6<>"",J6<>"",K6<>"",L6<>"",M6<>""),"ГОТОВО","НЕ ГОТОВО")) | Z6: =IF(Y6<>"ГОТОВО","", "Предварительное заключение: "&A6&", скв. "&B6&". МРП: "&E6&" сут. ГНО: "&F6&", типоразмер "&G6&", марка "&H6&". Событие: "&I6&". Признак: "&J6&". Узел: "&K6&". Предварительная причина: "&L6&". Основное осложнение: "&M6&IF(N6<>"","; сопутствующее: "&N6,"")&IF(O6<>"","; дополнительно: "&O6,"")&".")
E7: =IF(OR(C7="",D7=""),"",D7-C7) | Y7: =IF(AND(A7="",B7=""),"",IF(AND(A7<>"",B7<>"",C7<>"",D7<>"",F7<>"",G7<>"",H7<>"",ISERROR(SEARCH("по паспорту",G7)),ISERROR(SEARCH("по паспорту",H7)),I7<>"",J7<>"",K7<>"",L7<>"",M7<>""),"ГОТОВО","НЕ ГОТОВО")) | Z7: =IF(Y7<>"ГОТОВО","", "Предварительное заключение: "&A7&", скв. "&B7&". МРП: "&E7&" сут. ГНО: "&F7&", типоразмер "&G7&", марка "&H7&". Событие: "&I7&". Признак: "&J7&". Узел: "&K7&". Предварительная причина: "&L7&". Основное осложнение: "&M7&IF(N7<>"","; сопутствующее: "&N7,"")&IF(O7<>"","; дополнительно: "&O7,"")&".")
E8: =IF(OR(C8="",D8=""),"",D8-C8) | Y8: =IF(AND(A8="",B8=""),"",IF(AND(A8<>"",B8<>"",C8<>"",D8<>"",F8<>"",G8<>"",H8<>"",ISERROR(SEARCH("по паспорту",G8)),ISERROR(SEARCH("по паспорту",H8)),I8<>"",J8<>"",K8<>"",L8<>"",M8<>""),"ГОТОВО","НЕ ГОТОВО")) | Z8: =IF(Y8<>"ГОТОВО","", "Предварительное заключение: "&A8&", скв. "&B8&". МРП: "&E8&" сут. ГНО: "&F8&", типоразмер "&G8&", марка "&H8&". Событие: "&I8&". Признак: "&J8&". Узел: "&K8&". Предварительная причина: "&L8&". Основное осложнение: "&M8&IF(N8<>"","; сопутствующее: "&N8,"")&IF(O8<>"","; дополнительно: "&O8,"")&".")
E9: =IF(OR(C9="",D9=""),"",D9-C9) | Y9: =IF(AND(A9="",B9=""),"",IF(AND(A9<>"",B9<>"",C9<>"",D9<>"",F9<>"",G9<>"",H9<>"",ISERROR(SEARCH("по паспорту",G9)),ISERROR(SEARCH("по паспорту",H9)),I9<>"",J9<>"",K9<>"",L9<>"",M9<>""),"ГОТОВО","НЕ ГОТОВО")) | Z9: =IF(Y9<>"ГОТОВО","", "Предварительное заключение: "&A9&", скв. "&B9&". МРП: "&E9&" сут. ГНО: "&F9&", типоразмер "&G9&", марка "&H9&". Событие: "&I9&". Признак: "&J9&". Узел: "&K9&". Предварительная причина: "&L9&". Основное осложнение: "&M9&IF(N9<>"","; сопутствующее: "&N9,"")&IF(O9<>"","; дополнительно: "&O9,"")&".")
E10: =IF(OR(C10="",D10=""),"",D10-C10) | Y10: =IF(AND(A10="",B10=""),"",IF(AND(A10<>"",B10<>"",C10<>"",D10<>"",F10<>"",G10<>"",H10<>"",ISERROR(SEARCH("по паспорту",G10)),ISERROR(SEARCH("по паспорту",H10)),I10<>"",J10<>"",K10<>"",L10<>"",M10<>""),"ГОТОВО","НЕ ГОТОВО")) | Z10: =IF(Y10<>"ГОТОВО","", "Предварительное заключение: "&A10&", скв. "&B10&". МРП: "&E10&" сут. ГНО: "&F10&", типоразмер "&G10&", марка "&H10&". Событие: "&I10&". Признак: "&J10&". Узел: "&K10&". Предварительная причина: "&L10&". Основное осложнение: "&M10&IF(N10<>"","; сопутствующее: "&N10,"")&IF(O10<>"","; дополнительно: "&O10,"")&".")
E11: =IF(OR(C11="",D11=""),"",D11-C11) | Y11: =IF(AND(A11="",B11=""),"",IF(AND(A11<>"",B11<>"",C11<>"",D11<>"",F11<>"",G11<>"",H11<>"",ISERROR(SEARCH("по паспорту",G11)),ISERROR(SEARCH("по паспорту",H11)),I11<>"",J11<>"",K11<>"",L11<>"",M11<>""),"ГОТОВО","НЕ ГОТОВО")) | Z11: =IF(Y11<>"ГОТОВО","", "Предварительное заключение: "&A11&", скв. "&B11&". МРП: "&E11&" сут. ГНО: "&F11&", типоразмер "&G11&", марка "&H11&". Событие: "&I11&". Признак: "&J11&". Узел: "&K11&". Предварительная причина: "&L11&". Основное осложнение: "&M11&IF(N11<>"","; сопутствующее: "&N11,"")&IF(O11<>"","; дополнительно: "&O11,"")&".")
E12: =IF(OR(C12="",D12=""),"",D12-C12) | Y12: =IF(AND(A12="",B12=""),"",IF(AND(A12<>"",B12<>"",C12<>"",D12<>"",F12<>"",G12<>"",H12<>"",ISERROR(SEARCH("по паспорту",G12)),ISERROR(SEARCH("по паспорту",H12)),I12<>"",J12<>"",K12<>"",L12<>"",M12<>""),"ГОТОВО","НЕ ГОТОВО")) | Z12: =IF(Y12<>"ГОТОВО","", "Предварительное заключение: "&A12&", скв. "&B12&". МРП: "&E12&" сут. ГНО: "&F12&", типоразмер "&G12&", марка "&H12&". Событие: "&I12&". Признак: "&J12&". Узел: "&K12&". Предварительная причина: "&L12&". Основное осложнение: "&M12&IF(N12<>"","; сопутствующее: "&N12,"")&IF(O12<>"","; дополнительно: "&O12,"")&".")
E13: =IF(OR(C13="",D13=""),"",D13-C13) | Y13: =IF(AND(A13="",B13=""),"",IF(AND(A13<>"",B13<>"",C13<>"",D13<>"",F13<>"",G13<>"",H13<>"",ISERROR(SEARCH("по паспорту",G13)),ISERROR(SEARCH("по паспорту",H13)),I13<>"",J13<>"",K13<>"",L13<>"",M13<>""),"ГОТОВО","НЕ ГОТОВО")) | Z13: =IF(Y13<>"ГОТОВО","", "Предварительное заключение: "&A13&", скв. "&B13&". МРП: "&E13&" сут. ГНО: "&F13&", типоразмер "&G13&", марка "&H13&". Событие: "&I13&". Признак: "&J13&". Узел: "&K13&". Предварительная причина: "&L13&". Основное осложнение: "&M13&IF(N13<>"","; сопутствующее: "&N13,"")&IF(O13<>"","; дополнительно: "&O13,"")&".")
E14: =IF(OR(C14="",D14=""),"",D14-C14) | Y14: =IF(AND(A14="",B14=""),"",IF(AND(A14<>"",B14<>"",C14<>"",D14<>"",F14<>"",G14<>"",H14<>"",ISERROR(SEARCH("по паспорту",G14)),ISERROR(SEARCH("по паспорту",H14)),I14<>"",J14<>"",K14<>"",L14<>"",M14<>""),"ГОТОВО","НЕ ГОТОВО")) | Z14: =IF(Y14<>"ГОТОВО","", "Предварительное заключение: "&A14&", скв. "&B14&". МРП: "&E14&" сут. ГНО: "&F14&", типоразмер "&G14&", марка "&H14&". Событие: "&I14&". Признак: "&J14&". Узел: "&K14&". Предварительная причина: "&L14&". Основное осложнение: "&M14&IF(N14<>"","; сопутствующее: "&N14,"")&IF(O14<>"","; дополнительно: "&O14,"")&".")
E15: =IF(OR(C15="",D15=""),"",D15-C15) | Y15: =IF(AND(A15="",B15=""),"",IF(AND(A15<>"",B15<>"",C15<>"",D15<>"",F15<>"",G15<>"",H15<>"",ISERROR(SEARCH("по паспорту",G15)),ISERROR(SEARCH("по паспорту",H15)),I15<>"",J15<>"",K15<>"",L15<>"",M15<>""),"ГОТОВО","НЕ ГОТОВО")) | Z15: =IF(Y15<>"ГОТОВО","", "Предварительное заключение: "&A15&", скв. "&B15&". МРП: "&E15&" сут. ГНО: "&F15&", типоразмер "&G15&", марка "&H15&". Событие: "&I15&". Признак: "&J15&". Узел: "&K15&". Предварительная причина: "&L15&". Основное осложнение: "&M15&IF(N15<>"","; сопутствующее: "&N15,"")&IF(O15<>"","; дополнительно: "&O15,"")&".")
E16: =IF(OR(C16="",D16=""),"",D16-C16) | Y16: =IF(AND(A16="",B16=""),"",IF(AND(A16<>"",B16<>"",C16<>"",D16<>"",F16<>"",G16<>"",H16<>"",ISERROR(SEARCH("по паспорту",G16)),ISERROR(SEARCH("по паспорту",H16)),I16<>"",J16<>"",K16<>"",L16<>"",M16<>""),"ГОТОВО","НЕ ГОТОВО")) | Z16: =IF(Y16<>"ГОТОВО","", "Предварительное заключение: "&A16&", скв. "&B16&". МРП: "&E16&" сут. ГНО: "&F16&", типоразмер "&G16&", марка "&H16&". Событие: "&I16&". Признак: "&J16&". Узел: "&K16&". Предварительная причина: "&L16&". Основное осложнение: "&M16&IF(N16<>"","; сопутствующее: "&N16,"")&IF(O16<>"","; дополнительно: "&O16,"")&".")
... E1204: =IF(OR(C1204="",D1204=""),"",D1204-C1204) | Y1204: =IF(AND(A1204="",B1204=""),"",IF(AND(A1204<>"",B1204<>"",C1204<>"",D1204<>"",F1204<>"",G1204<>"",H1204<>"",ISERROR(SEARCH("по паспорту",G1204)),ISERROR(SEARCH("по паспорту",H1204)),I1204<>"",J1204<>"",K1204<>"",L1204<>"",M1204<>""),"ГОТОВО","НЕ ГОТОВО")) | Z1204: =IF(Y1204<>"ГОТОВО","", "Предварительное заключение: "&A1204&", скв. "&B1204&". МРП: "&E1204&" сут. ГНО: "&F1204&", типоразмер "&G1204&", марка "&H1204&". Событие: "&I1204&". Признак: "&J1204&". Узел: "&K1204&". Предварительная причина: "&L1204&". Основное осложнение: "&M1204&IF(N1204<>"","; сопутствующее: "&N1204,"")&IF(O1204<>"","; дополнительно: "&O1204,"")&".")

Sheet История отказов
A1: РОСА — ПОДРОБНЫЙ НАКОПИТЕЛЬ ИСТОРИИ ОТКАЗОВ
A2: Общие сведения автоматически дублируются с листа «Оперативный ввод». Подробную комплектацию оборудования, методы и результаты расследования дополняйте здесь.
A3: ОБЪЕКТ | C3: ЦИКЛ И ГНО | J3: ПРЕДВАРИТЕЛЬНОЕ ЗАКЛЮЧЕНИЕ | R3: ПОЛНОЕ РАССЛЕДОВАНИЕ | AD3: НАСОС | AF3: НКТ | AJ3: ДВИГАТЕЛЬ | AN3: КАБЕЛЬ | AQ3: УДЛИНИТЕЛЬ | AS3: ГИДРОЗАЩИТА | AW3: ТМС | BB3: ЗАКЛЮЧЕНИЕ КОМИССИИ | BD3: ИТОГ | BF3: КОММЕНТАРИЙ
A4: Месторождение* | B4: № скважины* | C4: Дата пуска* | D4: Дата отказа / окончания* | E4: МРП, сут. (авто) | F4: Способ эксплуатации* | G4: Типоразмер ГНО* | H4: Марка ГНО* | I4: Тип события* | J4: Признак / предпосылка* | K4: Отказавший узел* | L4: Предварительная причина* | M4: Основная категория осложнения* | N4: Сопутствующее осложнение 1 | O4: Сопутствующее осложнение 2 | P4: Статус предварительного (авто) | Q4: Предварительное заключение (авто) | R4: [ДОП] ТКРС 1 | S4: [ДОП] ТКРС 2 | T4: [ДОП] Вид повреждения | U4: [ДОП] Итоговая причина | V4: [ДОП] Уточнённая категория осложнения | W4: [ДОП] Метод до отказа 1 | X4: [ДОП] Метод до отказа 2 | Y4: [ДОП] Метод после отказа 1 | Z4: [ДОП] Метод после отказа 2 | AA4: [ДОП] Подтверждение | AB4: [ДОП] Статус расследования | AC4: [ДОП] Достоверность | AD4: Номинальная подача / размер (ШГН) | AE4: Производитель насоса | AF4: тип НКТ | AG4: длина НКТ | AH4: год НКТ | AI4: СПО | AJ4: состояние до спуска | AK4: Производитель двигателя | AL4: типоразмер двигателя | AM4: год двигателя | AN4: состояние до спуска | AO4: типоразмер кабеля | AP4: длина кабеля | AQ4: состояние до спуска | AR4: типоразмер удлинителя | AS4: длина удлинителя | AT4: состояние до спуска | AU4: Производитель гидрозащиты | AV4: типоразмер гидрозащиты | AW4: год гидрозащиты | AX4: состояние до спуска | AY4: Производитель ТМС | AZ4: типоразмер ТМС | BA4: год ТМС | BB4: [ДОП] Заключение комиссии / акт | BC4: [ДОП] Источник / документ | BD4: Статус полного (авто) | BE4: Полное заключение (авто) | BF4: Комментарий
A5: =IF('Оперативный ввод'!A5="","",'Оперативный ввод'!A5) | B5: =IF('Оперативный ввод'!B5="","",'Оперативный ввод'!B5) | C5: =IF('Оперативный ввод'!C5="","",'Оперативный ввод'!C5) | D5: =IF('Оперативный ввод'!D5="","",'Оперативный ввод'!D5) | E5: =IF(OR(C5="",D5=""),"",D5-C5) | F5: =IF('Оперативный ввод'!F5="","",'Оперативный ввод'!F5) | G5: =IF('Оперативный ввод'!G5="","",'Оперативный ввод'!G5) | H5: =IF('Оперативный ввод'!H5="","",'Оперативный ввод'!H5) | I5: =IF('Оперативный ввод'!I5="","",'Оперативный ввод'!I5) | J5: =IF('Оперативный ввод'!J5="","",'Оперативный ввод'!J5) | K5: =IF('Оперативный ввод'!K5="","",'Оперативный ввод'!K5) | L5: =IF('Оперативный ввод'!L5="","",'Оперативный ввод'!L5) | M5: =IF('Оперативный ввод'!M5="","",'Оперативный ввод'!M5) | ... O5: =IF('Оперативный ввод'!O5="","",'Оперативный ввод'!O5) | P5: =IF(AND(A5="",B5=""),"",IF(AND(A5<>"",B5<>"",C5<>"",D5<>"",F5<>"",G5<>"",H5<>"",ISERROR(SEARCH("по паспорту",G5)),ISERROR(SEARCH("по паспорту",H5)),I5<>"",J5<>"",K5<>"",L5<>"",M5<>""),"ГОТОВО","НЕ ГОТОВО")) | Q5: =IF(P5<>"ГОТОВО","", "Предварительное заключение: "&A5&", скв. "&B5&". МРП: "&E5&" сут. ГНО: "&F5&", типоразмер "&G5&", марка "&H5&". Событие: "&I5&". Признак: "&J5&". Узел: "&K5&". Предварительная причина: "&L5&". Основное осложнение: "&M5&IF(N5<>"","; сопутствующее: "&N5,"")&IF(O5<>"","; дополнительно: "&O5,"")&".") | R5: =IF('Оперативный ввод'!P5="","",'Оперативный ввод'!P5) | S5: =IF('Оперативный ввод'!Q5="","",'Оперативный ввод'!Q5) | T5: =IF('Оперативный ввод'!R5="","",'Оперативный ввод'!R5) | U5: =IF('Оперативный ввод'!S5="","",'Оперативный ввод'!S5) | V5: =IF('Оперативный ввод'!T5="","",'Оперативный ввод'!T5) | AA5: =IF('Оперативный ввод'!U5="","",'Оперативный ввод'!U5) | AB5: =IF('Оперативный ввод'!V5="","",'Оперативный ввод'!V5) | AC5: =IF('Оперативный ввод'!W5="","",'Оперативный ввод'!W5) | BD5: =IF(AND(A5="",B5=""),"",IF(AND(P5="ГОТОВО",R5<>"",T5<>"",U5<>"",AA5<>"",AB5<>"",AC5<>"",BB5<>"",BC5<>""),"ГОТОВО","НЕ ГОТОВО")) | BE5: =IF(BD5<>"ГОТОВО","","Полное заключение: "&A5&", скв. "&B5&". МРП: "&E5&" сут. ГНО: "&F5&"; причина: "&U5&"; категория: "&V5&"; решение комиссии: "&BB5&".") | BF5: =IF('Оперативный ввод'!X5="","",'Оперативный ввод'!X5)
A6: =IF('Оперативный ввод'!A6="","",'Оперативный ввод'!A6) | B6: =IF('Оперативный ввод'!B6="","",'Оперативный ввод'!B6) | C6: =IF('Оперативный ввод'!C6="","",'Оперативный ввод'!C6) | D6: =IF('Оперативный ввод'!D6="","",'Оперативный ввод'!D6) | E6: =IF(OR(C6="",D6=""),"",D6-C6) | F6: =IF('Оперативный ввод'!F6="","",'Оперативный ввод'!F6) | G6: =IF('Оперативный ввод'!G6="","",'Оперативный ввод'!G6) | H6: =IF('Оперативный ввод'!H6="","",'Оперативный ввод'!H6) | I6: =IF('Оперативный ввод'!I6="","",'Оперативный ввод'!I6) | J6: =IF('Оперативный ввод'!J6="","",'Оперативный ввод'!J6) | K6: =IF('Оперативный ввод'!K6="","",'Оперативный ввод'!K6) | L6: =IF('Оперативный ввод'!L6="","",'Оперативный ввод'!L6) | M6: =IF('Оперативный ввод'!M6="","",'Оперативный ввод'!M6) | ... O6: =IF('Оперативный ввод'!O6="","",'Оперативный ввод'!O6) | P6: =IF(AND(A6="",B6=""),"",IF(AND(A6<>"",B6<>"",C6<>"",D6<>"",F6<>"",G6<>"",H6<>"",ISERROR(SEARCH("по паспорту",G6)),ISERROR(SEARCH("по паспорту",H6)),I6<>"",J6<>"",K6<>"",L6<>"",M6<>""),"ГОТОВО","НЕ ГОТОВО")) | Q6: =IF(P6<>"ГОТОВО","", "Предварительное заключение: "&A6&", скв. "&B6&". МРП: "&E6&" сут. ГНО: "&F6&", типоразмер "&G6&", марка "&H6&". Событие: "&I6&". Признак: "&J6&". Узел: "&K6&". Предварительная причина: "&L6&". Основное осложнение: "&M6&IF(N6<>"","; сопутствующее: "&N6,"")&IF(O6<>"","; дополнительно: "&O6,"")&".") | R6: =IF('Оперативный ввод'!P6="","",'Оперативный ввод'!P6) | S6: =IF('Оперативный ввод'!Q6="","",'Оперативный ввод'!Q6) | T6: =IF('Оперативный ввод'!R6="","",'Оперативный ввод'!R6) | U6: =IF('Оперативный ввод'!S6="","",'Оперативный ввод'!S6) | V6: =IF('Оперативный ввод'!T6="","",'Оперативный ввод'!T6) | AA6: =IF('Оперативный ввод'!U6="","",'Оперативный ввод'!U6) | AB6: =IF('Оперативный ввод'!V6="","",'Оперативный ввод'!V6) | AC6: =IF('Оперативный ввод'!W6="","",'Оперативный ввод'!W6) | BD6: =IF(AND(A6="",B6=""),"",IF(AND(P6="ГОТОВО",R6<>"",T6<>"",U6<>"",AA6<>"",AB6<>"",AC6<>"",BB6<>"",BC6<>""),"ГОТОВО","НЕ ГОТОВО")) | BE6: =IF(BD6<>"ГОТОВО","","Полное заключение: "&A6&", скв. "&B6&". МРП: "&E6&" сут. ГНО: "&F6&"; причина: "&U6&"; категория: "&V6&"; решение комиссии: "&BB6&".") | BF6: =IF('Оперативный ввод'!X6="","",'Оперативный ввод'!X6)
A7: =IF('Оперативный ввод'!A7="","",'Оперативный ввод'!A7) | B7: =IF('Оперативный ввод'!B7="","",'Оперативный ввод'!B7) | C7: =IF('Оперативный ввод'!C7="","",'Оперативный ввод'!C7) | D7: =IF('Оперативный ввод'!D7="","",'Оперативный ввод'!D7) | E7: =IF(OR(C7="",D7=""),"",D7-C7) | F7: =IF('Оперативный ввод'!F7="","",'Оперативный ввод'!F7) | G7: =IF('Оперативный ввод'!G7="","",'Оперативный ввод'!G7) | H7: =IF('Оперативный ввод'!H7="","",'Оперативный ввод'!H7) | I7: =IF('Оперативный ввод'!I7="","",'Оперативный ввод'!I7) | J7: =IF('Оперативный ввод'!J7="","",'Оперативный ввод'!J7) | K7: =IF('Оперативный ввод'!K7="","",'Оперативный ввод'!K7) | L7: =IF('Оперативный ввод'!L7="","",'Оперативный ввод'!L7) | M7: =IF('Оперативный ввод'!M7="","",'Оперативный ввод'!M7) | ... O7: =IF('Оперативный ввод'!O7="","",'Оперативный ввод'!O7) | P7: =IF(AND(A7="",B7=""),"",IF(AND(A7<>"",B7<>"",C7<>"",D7<>"",F7<>"",G7<>"",H7<>"",ISERROR(SEARCH("по паспорту",G7)),ISERROR(SEARCH("по паспорту",H7)),I7<>"",J7<>"",K7<>"",L7<>"",M7<>""),"ГОТОВО","НЕ ГОТОВО")) | Q7: =IF(P7<>"ГОТОВО","", "Предварительное заключение: "&A7&", скв. "&B7&". МРП: "&E7&" сут. ГНО: "&F7&", типоразмер "&G7&", марка "&H7&". Событие: "&I7&". Признак: "&J7&". Узел: "&K7&". Предварительная причина: "&L7&". Основное осложнение: "&M7&IF(N7<>"","; сопутствующее: "&N7,"")&IF(O7<>"","; дополнительно: "&O7,"")&".") | R7: =IF('Оперативный ввод'!P7="","",'Оперативный ввод'!P7) | S7: =IF('Оперативный ввод'!Q7="","",'Оперативный ввод'!Q7) | T7: =IF('Оперативный ввод'!R7="","",'Оперативный ввод'!R7) | U7: =IF('Оперативный ввод'!S7="","",'Оперативный ввод'!S7) | V7: =IF('Оперативный ввод'!T7="","",'Оперативный ввод'!T7) | AA7: =IF('Оперативный ввод'!U7="","",'Оперативный ввод'!U7) | AB7: =IF('Оперативный ввод'!V7="","",'Оперативный ввод'!V7) | AC7: =IF('Оперативный ввод'!W7="","",'Оперативный ввод'!W7) | BD7: =IF(AND(A7="",B7=""),"",IF(AND(P7="ГОТОВО",R7<>"",T7<>"",U7<>"",AA7<>"",AB7<>"",AC7<>"",BB7<>"",BC7<>""),"ГОТОВО","НЕ ГОТОВО")) | BE7: =IF(BD7<>"ГОТОВО","","Полное заключение: "&A7&", скв. "&B7&". МРП: "&E7&" сут. ГНО: "&F7&"; причина: "&U7&"; категория: "&V7&"; решение комиссии: "&BB7&".") | BF7: =IF('Оперативный ввод'!X7="","",'Оперативный ввод'!X7)
A8: =IF('Оперативный ввод'!A8="","",'Оперативный ввод'!A8) | B8: =IF('Оперативный ввод'!B8="","",'Оперативный ввод'!B8) | C8: =IF('Оперативный ввод'!C8="","",'Оперативный ввод'!C8) | D8: =IF('Оперативный ввод'!D8="","",'Оперативный ввод'!D8) | E8: =IF(OR(C8="",D8=""),"",D8-C8) | F8: =IF('Оперативный ввод'!F8="","",'Оперативный ввод'!F8) | G8: =IF('Оперативный ввод'!G8="","",'Оперативный ввод'!G8) | H8: =IF('Оперативный ввод'!H8="","",'Оперативный ввод'!H8) | I8: =IF('Оперативный ввод'!I8="","",'Оперативный ввод'!I8) | J8: =IF('Оперативный ввод'!J8="","",'Оперативный ввод'!J8) | K8: =IF('Оперативный ввод'!K8="","",'Оперативный ввод'!K8) | L8: =IF('Оперативный ввод'!L8="","",'Оперативный ввод'!L8) | M8: =IF('Оперативный ввод'!M8="","",'Оперативный ввод'!M8) | ... O8: =IF('Оперативный ввод'!O8="","",'Оперативный ввод'!O8) | P8: =IF(AND(A8="",B8=""),"",IF(AND(A8<>"",B8<>"",C8<>"",D8<>"",F8<>"",G8<>"",H8<>"",ISERROR(SEARCH("по паспорту",G8)),ISERROR(SEARCH("по паспорту",H8)),I8<>"",J8<>"",K8<>"",L8<>"",M8<>""),"ГОТОВО","НЕ ГОТОВО")) | Q8: =IF(P8<>"ГОТОВО","", "Предварительное заключение: "&A8&", скв. "&B8&". МРП: "&E8&" сут. ГНО: "&F8&", типоразмер "&G8&", марка "&H8&". Событие: "&I8&". Признак: "&J8&". Узел: "&K8&". Предварительная причина: "&L8&". Основное осложнение: "&M8&IF(N8<>"","; сопутствующее: "&N8,"")&IF(O8<>"","; дополнительно: "&O8,"")&".") | R8: =IF('Оперативный ввод'!P8="","",'Оперативный ввод'!P8) | S8: =IF('Оперативный ввод'!Q8="","",'Оперативный ввод'!Q8) | T8: =IF('Оперативный ввод'!R8="","",'Оперативный ввод'!R8) | U8: =IF('Оперативный ввод'!S8="","",'Оперативный ввод'!S8) | V8: =IF('Оперативный ввод'!T8="","",'Оперативный ввод'!T8) | AA8: =IF('Оперативный ввод'!U8="","",'Оперативный ввод'!U8) | AB8: =IF('Оперативный ввод'!V8="","",'Оперативный ввод'!V8) | AC8: =IF('Оперативный ввод'!W8="","",'Оперативный ввод'!W8) | BD8: =IF(AND(A8="",B8=""),"",IF(AND(P8="ГОТОВО",R8<>"",T8<>"",U8<>"",AA8<>"",AB8<>"",AC8<>"",BB8<>"",BC8<>""),"ГОТОВО","НЕ ГОТОВО")) | BE8: =IF(BD8<>"ГОТОВО","","Полное заключение: "&A8&", скв. "&B8&". МРП: "&E8&" сут. ГНО: "&F8&"; причина: "&U8&"; категория: "&V8&"; решение комиссии: "&BB8&".") | BF8: =IF('Оперативный ввод'!X8="","",'Оперативный ввод'!X8)
A9: =IF('Оперативный ввод'!A9="","",'Оперативный ввод'!A9) | B9: =IF('Оперативный ввод'!B9="","",'Оперативный ввод'!B9) | C9: =IF('Оперативный ввод'!C9="","",'Оперативный ввод'!C9) | D9: =IF('Оперативный ввод'!D9="","",'Оперативный ввод'!D9) | E9: =IF(OR(C9="",D9=""),"",D9-C9) | F9: =IF('Оперативный ввод'!F9="","",'Оперативный ввод'!F9) | G9: =IF('Оперативный ввод'!G9="","",'Оперативный ввод'!G9) | H9: =IF('Оперативный ввод'!H9="","",'Оперативный ввод'!H9) | I9: =IF('Оперативный ввод'!I9="","",'Оперативный ввод'!I9) | J9: =IF('Оперативный ввод'!J9="","",'Оперативный ввод'!J9) | K9: =IF('Оперативный ввод'!K9="","",'Оперативный ввод'!K9) | L9: =IF('Оперативный ввод'!L9="","",'Оперативный ввод'!L9) | M9: =IF('Оперативный ввод'!M9="","",'Оперативный ввод'!M9) | ... O9: =IF('Оперативный ввод'!O9="","",'Оперативный ввод'!O9) | P9: =IF(AND(A9="",B9=""),"",IF(AND(A9<>"",B9<>"",C9<>"",D9<>"",F9<>"",G9<>"",H9<>"",ISERROR(SEARCH("по паспорту",G9)),ISERROR(SEARCH("по паспорту",H9)),I9<>"",J9<>"",K9<>"",L9<>"",M9<>""),"ГОТОВО","НЕ ГОТОВО")) | Q9: =IF(P9<>"ГОТОВО","", "Предварительное заключение: "&A9&", скв. "&B9&". МРП: "&E9&" сут. ГНО: "&F9&", типоразмер "&G9&", марка "&H9&". Событие: "&I9&". Признак: "&J9&". Узел: "&K9&". Предварительная причина: "&L9&". Основное осложнение: "&M9&IF(N9<>"","; сопутствующее: "&N9,"")&IF(O9<>"","; дополнительно: "&O9,"")&".") | R9: =IF('Оперативный ввод'!P9="","",'Оперативный ввод'!P9) | S9: =IF('Оперативный ввод'!Q9="","",'Оперативный ввод'!Q9) | T9: =IF('Оперативный ввод'!R9="","",'Оперативный ввод'!R9) | U9: =IF('Оперативный ввод'!S9="","",'Оперативный ввод'!S9) | V9: =IF('Оперативный ввод'!T9="","",'Оперативный ввод'!T9) | AA9: =IF('Оперативный ввод'!U9="","",'Оперативный ввод'!U9) | AB9: =IF('Оперативный ввод'!V9="","",'Оперативный ввод'!V9) | AC9: =IF('Оперативный ввод'!W9="","",'Оперативный ввод'!W9) | BD9: =IF(AND(A9="",B9=""),"",IF(AND(P9="ГОТОВО",R9<>"",T9<>"",U9<>"",AA9<>"",AB9<>"",AC9<>"",BB9<>"",BC9<>""),"ГОТОВО","НЕ ГОТОВО")) | BE9: =IF(BD9<>"ГОТОВО","","Полное заключение: "&A9&", скв. "&B9&". МРП: "&E9&" сут. ГНО: "&F9&"; причина: "&U9&"; категория: "&V9&"; решение комиссии: "&BB9&".") | BF9: =IF('Оперативный ввод'!X9="","",'Оперативный ввод'!X9)
A10: =IF('Оперативный ввод'!A10="","",'Оперативный ввод'!A10) | B10: =IF('Оперативный ввод'!B10="","",'Оперативный ввод'!B10) | C10: =IF('Оперативный ввод'!C10="","",'Оперативный ввод'!C10) | D10: =IF('Оперативный ввод'!D10="","",'Оперативный ввод'!D10) | E10: =IF(OR(C10="",D10=""),"",D10-C10) | F10: =IF('Оперативный ввод'!F10="","",'Оперативный ввод'!F10) | G10: =IF('Оперативный ввод'!G10="","",'Оперативный ввод'!G10) | H10: =IF('Оперативный ввод'!H10="","",'Оперативный ввод'!H10) | I10: =IF('Оперативный ввод'!I10="","",'Оперативный ввод'!I10) | J10: =IF('Оперативный ввод'!J10="","",'Оперативный ввод'!J10) | K10: =IF('Оперативный ввод'!K10="","",'Оперативный ввод'!K10) | L10: =IF('Оперативный ввод'!L10="","",'Оперативный ввод'!L10) | M10: =IF('Оперативный ввод'!M10="","",'Оперативный ввод'!M10) | ... O10: =IF('Оперативный ввод'!O10="","",'Оперативный ввод'!O10) | P10: =IF(AND(A10="",B10=""),"",IF(AND(A10<>"",B10<>"",C10<>"",D10<>"",F10<>"",G10<>"",H10<>"",ISERROR(SEARCH("по паспорту",G10)),ISERROR(SEARCH("по паспорту",H10)),I10<>"",J10<>"",K10<>"",L10<>"",M10<>""),"ГОТОВО","НЕ ГОТОВО")) | Q10: =IF(P10<>"ГОТОВО","", "Предварительное заключение: "&A10&", скв. "&B10&". МРП: "&E10&" сут. ГНО: "&F10&", типоразмер "&G10&", марка "&H10&". Событие: "&I10&". Признак: "&J10&". Узел: "&K10&". Предварительная причина: "&L10&". Основное осложнение: "&M10&IF(N10<>"","; сопутствующее: "&N10,"")&IF(O10<>"","; дополнительно: "&O10,"")&".") | R10: =IF('Оперативный ввод'!P10="","",'Оперативный ввод'!P10) | S10: =IF('Оперативный ввод'!Q10="","",'Оперативный ввод'!Q10) | T10: =IF('Оперативный ввод'!R10="","",'Оперативный ввод'!R10) | U10: =IF('Оперативный ввод'!S10="","",'Оперативный ввод'!S10) | V10: =IF('Оперативный ввод'!T10="","",'Оперативный ввод'!T10) | AA10: =IF('Оперативный ввод'!U10="","",'Оперативный ввод'!U10) | AB10: =IF('Оперативный ввод'!V10="","",'Оперативный ввод'!V10) | AC10: =IF('Оперативный ввод'!W10="","",'Оперативный ввод'!W10) | BD10: =IF(AND(A10="",B10=""),"",IF(AND(P10="ГОТОВО",R10<>"",T10<>"",U10<>"",AA10<>"",AB10<>"",AC10<>"",BB10<>"",BC10<>""),"ГОТОВО","НЕ ГОТОВО")) | BE10: =IF(BD10<>"ГОТОВО","","Полное заключение: "&A10&", скв. "&B10&". МРП: "&E10&" сут. ГНО: "&F10&"; причина: "&U10&"; категория: "&V10&"; решение комиссии: "&BB10&".") | BF10: =IF('Оперативный ввод'!X10="","",'Оперативный ввод'!X10)
A11: =IF('Оперативный ввод'!A11="","",'Оперативный ввод'!A11) | B11: =IF('Оперативный ввод'!B11="","",'Оперативный ввод'!B11) | C11: =IF('Оперативный ввод'!C11="","",'Оперативный ввод'!C11) | D11: =IF('Оперативный ввод'!D11="","",'Оперативный ввод'!D11) | E11: =IF(OR(C11="",D11=""),"",D11-C11) | F11: =IF('Оперативный ввод'!F11="","",'Оперативный ввод'!F11) | G11: =IF('Оперативный ввод'!G11="","",'Оперативный ввод'!G11) | H11: =IF('Оперативный ввод'!H11="","",'Оперативный ввод'!H11) | I11: =IF('Оперативный ввод'!I11="","",'Оперативный ввод'!I11) | J11: =IF('Оперативный ввод'!J11="","",'Оперативный ввод'!J11) | K11: =IF('Оперативный ввод'!K11="","",'Оперативный ввод'!K11) | L11: =IF('Оперативный ввод'!L11="","",'Оперативный ввод'!L11) | M11: =IF('Оперативный ввод'!M11="","",'Оперативный ввод'!M11) | ... O11: =IF('Оперативный ввод'!O11="","",'Оперативный ввод'!O11) | P11: =IF(AND(A11="",B11=""),"",IF(AND(A11<>"",B11<>"",C11<>"",D11<>"",F11<>"",G11<>"",H11<>"",ISERROR(SEARCH("по паспорту",G11)),ISERROR(SEARCH("по паспорту",H11)),I11<>"",J11<>"",K11<>"",L11<>"",M11<>""),"ГОТОВО","НЕ ГОТОВО")) | Q11: =IF(P11<>"ГОТОВО","", "Предварительное заключение: "&A11&", скв. "&B11&". МРП: "&E11&" сут. ГНО: "&F11&", типоразмер "&G11&", марка "&H11&". Событие: "&I11&". Признак: "&J11&". Узел: "&K11&". Предварительная причина: "&L11&". Основное осложнение: "&M11&IF(N11<>"","; сопутствующее: "&N11,"")&IF(O11<>"","; дополнительно: "&O11,"")&".") | R11: =IF('Оперативный ввод'!P11="","",'Оперативный ввод'!P11) | S11: =IF('Оперативный ввод'!Q11="","",'Оперативный ввод'!Q11) | T11: =IF('Оперативный ввод'!R11="","",'Оперативный ввод'!R11) | U11: =IF('Оперативный ввод'!S11="","",'Оперативный ввод'!S11) | V11: =IF('Оперативный ввод'!T11="","",'Оперативный ввод'!T11) | AA11: =IF('Оперативный ввод'!U11="","",'Оперативный ввод'!U11) | AB11: =IF('Оперативный ввод'!V11="","",'Оперативный ввод'!V11) | AC11: =IF('Оперативный ввод'!W11="","",'Оперативный ввод'!W11) | BD11: =IF(AND(A11="",B11=""),"",IF(AND(P11="ГОТОВО",R11<>"",T11<>"",U11<>"",AA11<>"",AB11<>"",AC11<>"",BB11<>"",BC11<>""),"ГОТОВО","НЕ ГОТОВО")) | BE11: =IF(BD11<>"ГОТОВО","","Полное заключение: "&A11&", скв. "&B11&". МРП: "&E11&" сут. ГНО: "&F11&"; причина: "&U11&"; категория: "&V11&"; решение комиссии: "&BB11&".") | BF11: =IF('Оперативный ввод'!X11="","",'Оперативный ввод'!X11)
A12: =IF('Оперативный ввод'!A12="","",'Оперативный ввод'!A12) | B12: =IF('Оперативный ввод'!B12="","",'Оперативный ввод'!B12) | C12: =IF('Оперативный ввод'!C12="","",'Оперативный ввод'!C12) | D12: =IF('Оперативный ввод'!D12="","",'Оперативный ввод'!D12) | E12: =IF(OR(C12="",D12=""),"",D12-C12) | F12: =IF('Оперативный ввод'!F12="","",'Оперативный ввод'!F12) | G12: =IF('Оперативный ввод'!G12="","",'Оперативный ввод'!G12) | H12: =IF('Оперативный ввод'!H12="","",'Оперативный ввод'!H12) | I12: =IF('Оперативный ввод'!I12="","",'Оперативный ввод'!I12) | J12: =IF('Оперативный ввод'!J12="","",'Оперативный ввод'!J12) | K12: =IF('Оперативный ввод'!K12="","",'Оперативный ввод'!K12) | L12: =IF('Оперативный ввод'!L12="","",'Оперативный ввод'!L12) | M12: =IF('Оперативный ввод'!M12="","",'Оперативный ввод'!M12) | ... O12: =IF('Оперативный ввод'!O12="","",'Оперативный ввод'!O12) | P12: =IF(AND(A12="",B12=""),"",IF(AND(A12<>"",B12<>"",C12<>"",D12<>"",F12<>"",G12<>"",H12<>"",ISERROR(SEARCH("по паспорту",G12)),ISERROR(SEARCH("по паспорту",H12)),I12<>"",J12<>"",K12<>"",L12<>"",M12<>""),"ГОТОВО","НЕ ГОТОВО")) | Q12: =IF(P12<>"ГОТОВО","", "Предварительное заключение: "&A12&", скв. "&B12&". МРП: "&E12&" сут. ГНО: "&F12&", типоразмер "&G12&", марка "&H12&". Событие: "&I12&". Признак: "&J12&". Узел: "&K12&". Предварительная причина: "&L12&". Основное осложнение: "&M12&IF(N12<>"","; сопутствующее: "&N12,"")&IF(O12<>"","; дополнительно: "&O12,"")&".") | R12: =IF('Оперативный ввод'!P12="","",'Оперативный ввод'!P12) | S12: =IF('Оперативный ввод'!Q12="","",'Оперативный ввод'!Q12) | T12: =IF('Оперативный ввод'!R12="","",'Оперативный ввод'!R12) | U12: =IF('Оперативный ввод'!S12="","",'Оперативный ввод'!S12) | V12: =IF('Оперативный ввод'!T12="","",'Оперативный ввод'!T12) | AA12: =IF('Оперативный ввод'!U12="","",'Оперативный ввод'!U12) | AB12: =IF('Оперативный ввод'!V12="","",'Оперативный ввод'!V12) | AC12: =IF('Оперативный ввод'!W12="","",'Оперативный ввод'!W12) | BD12: =IF(AND(A12="",B12=""),"",IF(AND(P12="ГОТОВО",R12<>"",T12<>"",U12<>"",AA12<>"",AB12<>"",AC12<>"",BB12<>"",BC12<>""),"ГОТОВО","НЕ ГОТОВО")) | BE12: =IF(BD12<>"ГОТОВО","","Полное заключение: "&A12&", скв. "&B12&". МРП: "&E12&" сут. ГНО: "&F12&"; причина: "&U12&"; категория: "&V12&"; решение комиссии: "&BB12&".") | BF12: =IF('Оперативный ввод'!X12="","",'Оперативный ввод'!X12)
A13: =IF('Оперативный ввод'!A13="","",'Оперативный ввод'!A13) | B13: =IF('Оперативный ввод'!B13="","",'Оперативный ввод'!B13) | C13: =IF('Оперативный ввод'!C13="","",'Оперативный ввод'!C13) | D13: =IF('Оперативный ввод'!D13="","",'Оперативный ввод'!D13) | E13: =IF(OR(C13="",D13=""),"",D13-C13) | F13: =IF('Оперативный ввод'!F13="","",'Оперативный ввод'!F13) | G13: =IF('Оперативный ввод'!G13="","",'Оперативный ввод'!G13) | H13: =IF('Оперативный ввод'!H13="","",'Оперативный ввод'!H13) | I13: =IF('Оперативный ввод'!I13="","",'Оперативный ввод'!I13) | J13: =IF('Оперативный ввод'!J13="","",'Оперативный ввод'!J13) | K13: =IF('Оперативный ввод'!K13="","",'Оперативный ввод'!K13) | L13: =IF('Оперативный ввод'!L13="","",'Оперативный ввод'!L13) | M13: =IF('Оперативный ввод'!M13="","",'Оперативный ввод'!M13) | ... O13: =IF('Оперативный ввод'!O13="","",'Оперативный ввод'!O13) | P13: =IF(AND(A13="",B13=""),"",IF(AND(A13<>"",B13<>"",C13<>"",D13<>"",F13<>"",G13<>"",H13<>"",ISERROR(SEARCH("по паспорту",G13)),ISERROR(SEARCH("по паспорту",H13)),I13<>"",J13<>"",K13<>"",L13<>"",M13<>""),"ГОТОВО","НЕ ГОТОВО")) | Q13: =IF(P13<>"ГОТОВО","", "Предварительное заключение: "&A13&", скв. "&B13&". МРП: "&E13&" сут. ГНО: "&F13&", типоразмер "&G13&", марка "&H13&". Событие: "&I13&". Признак: "&J13&". Узел: "&K13&". Предварительная причина: "&L13&". Основное осложнение: "&M13&IF(N13<>"","; сопутствующее: "&N13,"")&IF(O13<>"","; дополнительно: "&O13,"")&".") | R13: =IF('Оперативный ввод'!P13="","",'Оперативный ввод'!P13) | S13: =IF('Оперативный ввод'!Q13="","",'Оперативный ввод'!Q13) | T13: =IF('Оперативный ввод'!R13="","",'Оперативный ввод'!R13) | U13: =IF('Оперативный ввод'!S13="","",'Оперативный ввод'!S13) | V13: =IF('Оперативный ввод'!T13="","",'Оперативный ввод'!T13) | AA13: =IF('Оперативный ввод'!U13="","",'Оперативный ввод'!U13) | AB13: =IF('Оперативный ввод'!V13="","",'Оперативный ввод'!V13) | AC13: =IF('Оперативный ввод'!W13="","",'Оперативный ввод'!W13) | BD13: =IF(AND(A13="",B13=""),"",IF(AND(P13="ГОТОВО",R13<>"",T13<>"",U13<>"",AA13<>"",AB13<>"",AC13<>"",BB13<>"",BC13<>""),"ГОТОВО","НЕ ГОТОВО")) | BE13: =IF(BD13<>"ГОТОВО","","Полное заключение: "&A13&", скв. "&B13&". МРП: "&E13&" сут. ГНО: "&F13&"; причина: "&U13&"; категория: "&V13&"; решение комиссии: "&BB13&".") | BF13: =IF('Оперативный ввод'!X13="","",'Оперативный ввод'!X13)
A14: =IF('Оперативный ввод'!A14="","",'Оперативный ввод'!A14) | B14: =IF('Оперативный ввод'!B14="","",'Оперативный ввод'!B14) | C14: =IF('Оперативный ввод'!C14="","",'Оперативный ввод'!C14) | D14: =IF('Оперативный ввод'!D14="","",'Оперативный ввод'!D14) | E14: =IF(OR(C14="",D14=""),"",D14-C14) | F14: =IF('Оперативный ввод'!F14="","",'Оперативный ввод'!F14) | G14: =IF('Оперативный ввод'!G14="","",'Оперативный ввод'!G14) | H14: =IF('Оперативный ввод'!H14="","",'Оперативный ввод'!H14) | I14: =IF('Оперативный ввод'!I14="","",'Оперативный ввод'!I14) | J14: =IF('Оперативный ввод'!J14="","",'Оперативный ввод'!J14) | K14: =IF('Оперативный ввод'!K14="","",'Оперативный ввод'!K14) | L14: =IF('Оперативный ввод'!L14="","",'Оперативный ввод'!L14) | M14: =IF('Оперативный ввод'!M14="","",'Оперативный ввод'!M14) | ... O14: =IF('Оперативный ввод'!O14="","",'Оперативный ввод'!O14) | P14: =IF(AND(A14="",B14=""),"",IF(AND(A14<>"",B14<>"",C14<>"",D14<>"",F14<>"",G14<>"",H14<>"",ISERROR(SEARCH("по паспорту",G14)),ISERROR(SEARCH("по паспорту",H14)),I14<>"",J14<>"",K14<>"",L14<>"",M14<>""),"ГОТОВО","НЕ ГОТОВО")) | Q14: =IF(P14<>"ГОТОВО","", "Предварительное заключение: "&A14&", скв. "&B14&". МРП: "&E14&" сут. ГНО: "&F14&", типоразмер "&G14&", марка "&H14&". Событие: "&I14&". Признак: "&J14&". Узел: "&K14&". Предварительная причина: "&L14&". Основное осложнение: "&M14&IF(N14<>"","; сопутствующее: "&N14,"")&IF(O14<>"","; дополнительно: "&O14,"")&".") | R14: =IF('Оперативный ввод'!P14="","",'Оперативный ввод'!P14) | S14: =IF('Оперативный ввод'!Q14="","",'Оперативный ввод'!Q14) | T14: =IF('Оперативный ввод'!R14="","",'Оперативный ввод'!R14) | U14: =IF('Оперативный ввод'!S14="","",'Оперативный ввод'!S14) | V14: =IF('Оперативный ввод'!T14="","",'Оперативный ввод'!T14) | AA14: =IF('Оперативный ввод'!U14="","",'Оперативный ввод'!U14) | AB14: =IF('Оперативный ввод'!V14="","",'Оперативный ввод'!V14) | AC14: =IF('Оперативный ввод'!W14="","",'Оперативный ввод'!W14) | BD14: =IF(AND(A14="",B14=""),"",IF(AND(P14="ГОТОВО",R14<>"",T14<>"",U14<>"",AA14<>"",AB14<>"",AC14<>"",BB14<>"",BC14<>""),"ГОТОВО","НЕ ГОТОВО")) | BE14: =IF(BD14<>"ГОТОВО","","Полное заключение: "&A14&", скв. "&B14&". МРП: "&E14&" сут. ГНО: "&F14&"; причина: "&U14&"; категория: "&V14&"; решение комиссии: "&BB14&".") | BF14: =IF('Оперативный ввод'!X14="","",'Оперативный ввод'!X14)
A15: =IF('Оперативный ввод'!A15="","",'Оперативный ввод'!A15) | B15: =IF('Оперативный ввод'!B15="","",'Оперативный ввод'!B15) | C15: =IF('Оперативный ввод'!C15="","",'Оперативный ввод'!C15) | D15: =IF('Оперативный ввод'!D15="","",'Оперативный ввод'!D15) | E15: =IF(OR(C15="",D15=""),"",D15-C15) | F15: =IF('Оперативный ввод'!F15="","",'Оперативный ввод'!F15) | G15: =IF('Оперативный ввод'!G15="","",'Оперативный ввод'!G15) | H15: =IF('Оперативный ввод'!H15="","",'Оперативный ввод'!H15) | I15: =IF('Оперативный ввод'!I15="","",'Оперативный ввод'!I15) | J15: =IF('Оперативный ввод'!J15="","",'Оперативный ввод'!J15) | K15: =IF('Оперативный ввод'!K15="","",'Оперативный ввод'!K15) | L15: =IF('Оперативный ввод'!L15="","",'Оперативный ввод'!L15) | M15: =IF('Оперативный ввод'!M15="","",'Оперативный ввод'!M15) | ... O15: =IF('Оперативный ввод'!O15="","",'Оперативный ввод'!O15) | P15: =IF(AND(A15="",B15=""),"",IF(AND(A15<>"",B15<>"",C15<>"",D15<>"",F15<>"",G15<>"",H15<>"",ISERROR(SEARCH("по паспорту",G15)),ISERROR(SEARCH("по паспорту",H15)),I15<>"",J15<>"",K15<>"",L15<>"",M15<>""),"ГОТОВО","НЕ ГОТОВО")) | Q15: =IF(P15<>"ГОТОВО","", "Предварительное заключение: "&A15&", скв. "&B15&". МРП: "&E15&" сут. ГНО: "&F15&", типоразмер "&G15&", марка "&H15&". Событие: "&I15&". Признак: "&J15&". Узел: "&K15&". Предварительная причина: "&L15&". Основное осложнение: "&M15&IF(N15<>"","; сопутствующее: "&N15,"")&IF(O15<>"","; дополнительно: "&O15,"")&".") | R15: =IF('Оперативный ввод'!P15="","",'Оперативный ввод'!P15) | S15: =IF('Оперативный ввод'!Q15="","",'Оперативный ввод'!Q15) | T15: =IF('Оперативный ввод'!R15="","",'Оперативный ввод'!R15) | U15: =IF('Оперативный ввод'!S15="","",'Оперативный ввод'!S15) | V15: =IF('Оперативный ввод'!T15="","",'Оперативный ввод'!T15) | AA15: =IF('Оперативный ввод'!U15="","",'Оперативный ввод'!U15) | AB15: =IF('Оперативный ввод'!V15="","",'Оперативный ввод'!V15) | AC15: =IF('Оперативный ввод'!W15="","",'Оперативный ввод'!W15) | BD15: =IF(AND(A15="",B15=""),"",IF(AND(P15="ГОТОВО",R15<>"",T15<>"",U15<>"",AA15<>"",AB15<>"",AC15<>"",BB15<>"",BC15<>""),"ГОТОВО","НЕ ГОТОВО")) | BE15: =IF(BD15<>"ГОТОВО","","Полное заключение: "&A15&", скв. "&B15&". МРП: "&E15&" сут. ГНО: "&F15&"; причина: "&U15&"; категория: "&V15&"; решение комиссии: "&BB15&".") | BF15: =IF('Оперативный ввод'!X15="","",'Оперативный ввод'!X15)
A16: =IF('Оперативный ввод'!A16="","",'Оперативный ввод'!A16) | B16: =IF('Оперативный ввод'!B16="","",'Оперативный ввод'!B16) | C16: =IF('Оперативный ввод'!C16="","",'Оперативный ввод'!C16) | D16: =IF('Оперативный ввод'!D16="","",'Оперативный ввод'!D16) | E16: =IF(OR(C16="",D16=""),"",D16-C16) | F16: =IF('Оперативный ввод'!F16="","",'Оперативный ввод'!F16) | G16: =IF('Оперативный ввод'!G16="","",'Оперативный ввод'!G16) | H16: =IF('Оперативный ввод'!H16="","",'Оперативный ввод'!H16) | I16: =IF('Оперативный ввод'!I16="","",'Оперативный ввод'!I16) | J16: =IF('Оперативный ввод'!J16="","",'Оперативный ввод'!J16) | K16: =IF('Оперативный ввод'!K16="","",'Оперативный ввод'!K16) | L16: =IF('Оперативный ввод'!L16="","",'Оперативный ввод'!L16) | M16: =IF('Оперативный ввод'!M16="","",'Оперативный ввод'!M16) | ... O16: =IF('Оперативный ввод'!O16="","",'Оперативный ввод'!O16) | P16: =IF(AND(A16="",B16=""),"",IF(AND(A16<>"",B16<>"",C16<>"",D16<>"",F16<>"",G16<>"",H16<>"",ISERROR(SEARCH("по паспорту",G16)),ISERROR(SEARCH("по паспорту",H16)),I16<>"",J16<>"",K16<>"",L16<>"",M16<>""),"ГОТОВО","НЕ ГОТОВО")) | Q16: =IF(P16<>"ГОТОВО","", "Предварительное заключение: "&A16&", скв. "&B16&". МРП: "&E16&" сут. ГНО: "&F16&", типоразмер "&G16&", марка "&H16&". Событие: "&I16&". Признак: "&J16&". Узел: "&K16&". Предварительная причина: "&L16&". Основное осложнение: "&M16&IF(N16<>"","; сопутствующее: "&N16,"")&IF(O16<>"","; дополнительно: "&O16,"")&".") | R16: =IF('Оперативный ввод'!P16="","",'Оперативный ввод'!P16) | S16: =IF('Оперативный ввод'!Q16="","",'Оперативный ввод'!Q16) | T16: =IF('Оперативный ввод'!R16="","",'Оперативный ввод'!R16) | U16: =IF('Оперативный ввод'!S16="","",'Оперативный ввод'!S16) | V16: =IF('Оперативный ввод'!T16="","",'Оперативный ввод'!T16) | AA16: =IF('Оперативный ввод'!U16="","",'Оперативный ввод'!U16) | AB16: =IF('Оперативный ввод'!V16="","",'Оперативный ввод'!V16) | AC16: =IF('Оперативный ввод'!W16="","",'Оперативный ввод'!W16) | BD16: =IF(AND(A16="",B16=""),"",IF(AND(P16="ГОТОВО",R16<>"",T16<>"",U16<>"",AA16<>"",AB16<>"",AC16<>"",BB16<>"",BC16<>""),"ГОТОВО","НЕ ГОТОВО")) | BE16: =IF(BD16<>"ГОТОВО","","Полное заключение: "&A16&", скв. "&B16&". МРП: "&E16&" сут. ГНО: "&F16&"; причина: "&U16&"; категория: "&V16&"; решение комиссии: "&BB16&".") | BF16: =IF('Оперативный ввод'!X16="","",'Оперативный ввод'!X16)
... A1204: =IF('Оперативный ввод'!A1204="","",'Оперативный ввод'!A1204) | B1204: =IF('Оперативный ввод'!B1204="","",'Оперативный ввод'!B1204) | C1204: =IF('Оперативный ввод'!C1204="","",'Оперативный ввод'!C1204) | D1204: =IF('Оперативный ввод'!D1204="","",'Оперативный ввод'!D1204) | E1204: =IF(OR(C1204="",D1204=""),"",D1204-C1204) | F1204: =IF('Оперативный ввод'!F1204="","",'Оперативный ввод'!F1204) | G1204: =IF('Оперативный ввод'!G1204="","",'Оперативный ввод'!G1204) | H1204: =IF('Оперативный ввод'!H1204="","",'Оперативный ввод'!H1204) | I1204: =IF('Оперативный ввод'!I1204="","",'Оперативный ввод'!I1204) | J1204: =IF('Оперативный ввод'!J1204="","",'Оперативный ввод'!J1204) | K1204: =IF('Оперативный ввод'!K1204="","",'Оперативный ввод'!K1204) | L1204: =IF('Оперативный ввод'!L1204="","",'Оперативный ввод'!L1204) | M1204: =IF('Оперативный ввод'!M1204="","",'Оперативный ввод'!M1204) | ... O1204: =IF('Оперативный ввод'!O1204="","",'Оперативный ввод'!O1204) | P1204: =IF(AND(A1204="",B1204=""),"",IF(AND(A1204<>"",B1204<>"",C1204<>"",D1204<>"",F1204<>"",G1204<>"",H1204<>"",ISERROR(SEARCH("по паспорту",G1204)),ISERROR(SEARCH("по паспорту",H1204)),I1204<>"",J1204<>"",K1204<>"",L1204<>"",M1204<>""),"ГОТОВО","НЕ ГОТОВО")) | Q1204: =IF(P1204<>"ГОТОВО","", "Предварительное заключение: "&A1204&", скв. "&B1204&". МРП: "&E1204&" сут. ГНО: "&F1204&", типоразмер "&G1204&", марка "&H1204&". Событие: "&I1204&". Признак: "&J1204&". Узел: "&K1204&". Предварительная причина: "&L1204&". Основное осложнение: "&M1204&IF(N1204<>"","; сопутствующее: "&N1204,"")&IF(O1204<>"","; дополнительно: "&O1204,"")&".") | R1204: =IF('Оперативный ввод'!P1204="","",'Оперативный ввод'!P1204) | S1204: =IF('Оперативный ввод'!Q1204="","",'Оперативный ввод'!Q1204) | T1204: =IF('Оперативный ввод'!R1204="","",'Оперативный ввод'!R1204) | U1204: =IF('Оперативный ввод'!S1204="","",'Оперативный ввод'!S1204) | V1204: =IF('Оперативный ввод'!T1204="","",'Оперативный ввод'!T1204) | AA1204: =IF('Оперативный ввод'!U1204="","",'Оперативный ввод'!U1204) | AB1204: =IF('Оперативный ввод'!V1204="","",'Оперативный ввод'!V1204) | AC1204: =IF('Оперативный ввод'!W1204="","",'Оперативный ввод'!W1204) | BD1204: =IF(AND(A1204="",B1204=""),"",IF(AND(P1204="ГОТОВО",R1204<>"",T1204<>"",U1204<>"",AA1204<>"",AB1204<>"",AC1204<>"",BB1204<>"",BC1204<>""),"ГОТОВО","НЕ ГОТОВО")) | BE1204: =IF(BD1204<>"ГОТОВО","","Полное заключение: "&A1204&", скв. "&B1204&". МРП: "&E1204&" сут. ГНО: "&F1204&"; причина: "&U1204&"; категория: "&V1204&"; решение комиссии: "&BB1204&".") | BF1204: =IF('Оперативный ввод'!X1204="","",'Оперативный ввод'!X1204)

Sheet Справочники
A1: Тип насоса | B1: Тип события | C1: Признак / предпосылка | D1: Отказавший узел | E1: Предварительная причина | F1: Основная категория | G1: Сопутствующая категория | H1: ТКРС | I1: Вид повреждения | J1: Итоговая причина | K1: Уточнённая категория | L1: Подтверждение | M1: Статус расследования | N1: Достоверность | O1: Метод борьбы | Q1: Поле | R1: Источник | S1: Правило | X1: Техническая проверка перечней | Y1: Вывод | Z1: Первичный источник | AA1: Типоразмер ГНО | AB1: Марка ГНО | AN1: pump | AO1: event | AP1: sign_esp | AQ1: sign_shgn | AR1: sign_vin | AS1: sign_npu | AT1: node_esp | AU1: node_shgn | AV1: node_vin | AW1: node_npu | AX1: cause_esp | AY1: cause_shgn | AZ1: comp | BA1: repair | BB1: damage_esp | BC1: damage_shgn | BD1: damage_vin | BE1: damage_npu | BF1: proof | BG1: status | BH1: confidence | BI1: method | BJ1: size_shgn | BK1: size_esp | BL1: size_evn | BM1: brand_shgn | BN1: brand_esp | BO1: brand_evn | BP1: brand_npu | BQ1: condition | BR1: tubing | BS1: workover | BT1: nominal | BU1: empty | BV1: size_shvn | BW1: size_npu | BX1: brand_shvn | BY1: cause_npu | BZ1: sign_shvn | CA1: sign_evn | CB1: node_shvn | CC1: node_evn | CD1: damage_shvn | CE1: damage_evn | CF1: size_all | CG1: brand_all | CH1: sign_all | CI1: node_all | CJ1: cause_all | CK1: damage_all | CL1: equip_motor_maker | CM1: equip_motor_size | CN1: equip_cable | CO1: equip_extension | CP1: equip_hydro_maker | CQ1: equip_hydro_size | CR1: equip_tms_maker | CS1: equip_tms_size | CT1: equip_pump_shgn | CU1: equip_pump_esp | CV1: equip_pump_evn | CW1: equip_pump_npu | CX1: equip_pump_shvn | CY1: equip_pump_all | CZ1: equip_nkt | DA1: equip_years | DB1: Новые годы: исходные вводы | DC1: Первое новое значение: equip_pump_shgn | DD1: Первое новое значение: equip_pump_esp | DE1: Первое новое значение: equip_pump_evn | DF1: Первое новое значение: equip_pump_shvn | DG1: Первое новое значение: equip_pump_npu | DH1: Первое новое значение: equip_pump_all | DI1: Первое новое значение: equip_motor_maker | DJ1: Первое новое значение: equip_hydro_maker | DK1: Первое новое значение: equip_tms_maker | DL1: Первое новое значение: equip_years
A2: ШГН | B2: Подтверждённый отказ | C2: Снижение подачи | D2: Насос | E2: 1.1 — Механическое повреждение кабеля [УЭЦН] | F2: А1 — АСПО | G2: А1 — АСПО | H2: КР1-1 — Отключение отдельных интервалов и пропластков объекта эксплуатации. | I2: Механическое повреждение | J2: 1.1 — Механическое повреждение кабеля [УЭЦН] | K2: А1 — АСПО | L2: Акт комиссии | M2: Расследование продолжается | N2: Не оценена | O2: Удаление АСПО горячей нефтью | Q2: Типоразмер ГНО | R2: ГОСТ 31835-2012; Новомет; ГМС Ливгидромаш — примеры, фактический паспорт имеет приоритет | S2: Выбор из списка; отсутствующий паспортный типоразмер/марку вписать вручную | X2: Разделение данных | Y2: Признак, отказавший узел, повреждение, причина и ремонт ведутся отдельно | Z2: https://www.iso.org/standard/64076.html | AA2: ШГН — 27 мм | AB2: ШГН — серия НВ1С-27 | AN2: ШГН | AO2: Подтверждённый отказ | AP2: Снижение подачи | AQ2: Снижение подачи | AR2: Снижение подачи | AS2: Снижение подачи | AT2: Насос | AU2: Насос | AV2: Насос | AW2: Насос | AX2: 1.1 — Механическое повреждение кабеля [УЭЦН] | AY2: 1.1 — Нарушение глубины спуска [УШГН] | AZ2: А1 — АСПО | BA2: КР1-1 — Отключение отдельных интервалов и пропластков объекта эксплуатации. | BB2: Механическое повреждение | BC2: Механическое повреждение | BD2: Механическое повреждение | BE2: Механическое повреждение | BF2: Акт комиссии | BG2: Расследование продолжается | BH2: Не оценена | BI2: Удаление АСПО горячей нефтью | BJ2: ШГН — 27 мм | BK2: ЭЦН — габарит 5 | BL2: ЭВН — габарит 5 | BM2: ШГН — серия НВ1С-27 | BN2: ЭЦН — серия УЭЦН-5 | BO2: ЭВН 5-16-1200 | BP2: НПУ-ВД-М | BQ2: Новое | BR2: НКТ гладкая | BS2: Спуск | BT2: 27 мм | BV2: ШВН — типоразмер уточнить по паспорту | BW2: НПУ-ВД — типоразмер уточнить по паспорту | BX2: ШВН — марку уточнить по паспорту | BY2: Причина НПУ-ВД — уточнить по результатам расследования | BZ2: Снижение подачи | CA2: Снижение подачи | CB2: Насос | CC2: Насос | CD2: Механическое повреждение | CE2: Механическое повреждение | CF2: ШГН — 27 мм | CG2: ШГН — серия НВ1С-27 | CH2: Снижение подачи | CI2: Насос | CJ2: 1.1 — Механическое повреждение кабеля [УЭЦН] | CK2: Механическое повреждение | CL2: Новомет | CM2: ПЭД — габарит 96 мм | CN2: КПпБП-120 3×10 | CO2: КПпБП-120 3×10 (удлинитель) | CP2: Новомет | CQ2: Модульная гидрозащита — 69 мм | CR2: Новомет | CS2: ТМС-Новомет | CT2: AmasEnergy | CU2: Новомет | CV2: ГМС Ливгидромаш | CW2: РИТЭК | CX2: Производитель ШВН — уточнить по паспорту | CY2: AmasEnergy | CZ2: НКТ гладкая 60×5 мм | DA2: 2035 | DB2: =IF('История отказов'!AH5="","",'История отказов'!AH5) | DC2: =IF('История отказов'!AE5="","",IF(AND(COUNTIF($CT$2:$CT$2,'История отказов'!AE5)=0,COUNTIFS('История отказов'!$F$5:F5,"ШГН",'История отказов'!$AE$5:AE5,'История отказов'!AE5)=1,'История отказов'!F5="ШГН"),1,"")) | DD2: =IF('История отказов'!AE5="","",IF(AND(COUNTIF($CU$2:$CU$3,'История отказов'!AE5)=0,COUNTIFS('История отказов'!$F$5:F5,"ЭЦН",'История отказов'!$AE$5:AE5,'История отказов'!AE5)=1,'История отказов'!F5="ЭЦН"),1,"")) | DE2: =IF('История отказов'!AE5="","",IF(AND(COUNTIF($CV$2:$CV$3,'История отказов'!AE5)=0,COUNTIFS('История отказов'!$F$5:F5,"ЭВН",'История отказов'!$AE$5:AE5,'История отказов'!AE5)=1,'История отказов'!F5="ЭВН"),1,"")) | DF2: =IF('История отказов'!AE5="","",IF(AND(COUNTIF($CX$2:$CX$2,'История отказов'!AE5)=0,COUNTIFS('История отказов'!$F$5:F5,"ШВН",'История отказов'!$AE$5:AE5,'История отказов'!AE5)=1,'История отказов'!F5="ШВН"),1,"")) | DG2: =IF('История отказов'!AE5="","",IF(AND(COUNTIF($CW$2:$CW$2,'История отказов'!AE5)=0,COUNTIFS('История отказов'!$F$5:F5,"НПУ-ВД",'История отказов'!$AE$5:AE5,'История отказов'!AE5)=1,'История отказов'!F5="НПУ-ВД"),1,"")) | DH2: =IF('История отказов'!AE5="","",IF(AND(COUNTIF($CY$2:$CY$6,'История отказов'!AE5)=0,COUNTIF('История отказов'!$AE$5:AE5,'История отказов'!AE5)=1),1,"")) | DI2: =IF('История отказов'!AK5="","",IF(AND(COUNTIF($CL$2:$CL$3,'История отказов'!AK5)=0,COUNTIF('История отказов'!$AK$5:AK5,'История отказов'!AK5)=1),1,"")) | DJ2: =IF('История отказов'!AU5="","",IF(AND(COUNTIF($CP$2:$CP$3,'История отказов'!AU5)=0,COUNTIF('История отказов'!$AU$5:AU5,'История отказов'!AU5)=1),1,"")) | DK2: =IF('История отказов'!AY5="","",IF(AND(COUNTIF($CR$2:$CR$2,'История отказов'!AY5)=0,COUNTIF('История отказов'!$AY$5:AY5,'История отказов'!AY5)=1),1,"")) | DL2: =IF(DB2="","",IF(AND(COUNTIF($DA$2:$DA$47,DB2)=0,COUNTIF($DB$2:DB2,DB2)=1),1,""))
A3: ЭЦН | B3: Предварительный отказ | C3: Отсутствие подачи | D3: Рабочие органы насоса | E3: 1.2 — Нарушение глубины спуска [УЭЦН] | F3: А2 — АСПО | G3: А2 — АСПО | H3: КР1-2 — Отключение отдельных пластов. | I3: Абразивный износ | J3: 1.2 — Нарушение глубины спуска [УЭЦН] | K3: А2 — АСПО | L3: Дефектовочная ведомость | M3: Вероятная причина | N3: Низкая | O3: Удаление АСПО углеводородным растворителем | Q3: Марка ГНО | R3: ГОСТ 31835-2012; Новомет; ГМС Ливгидромаш; РИТЭК — неполный перечень | S3: Выбор из списка; отсутствующий паспортный типоразмер/марку вписать вручную | X3: ЭЦН — наблюдения | Y3: Ток, температура, вибрация и ток утечки являются измерениями; диагноз требует анализа | Z3: https://www.slb.com/products-and-services/innovating-in-oil-and-gas/completions/artificial-lift/intelligent-lift/gauges/phoenix-xt150-downhole-monitoring-system | AA3: ШГН — 32 мм | AB3: ШГН — серия НВ1С-32 | AN3: ЭЦН | AO3: Предварительный отказ | AP3: Отсутствие подачи | AQ3: Отсутствие подачи | AR3: Отсутствие подачи | AS3: Отсутствие подачи | AT3: Рабочие органы насоса | AU3: Рабочие органы насоса | AV3: Рабочие органы насоса | AW3: Рабочие органы насоса | AX3: 1.2 — Нарушение глубины спуска [УЭЦН] | AY3: 1.2 — Некачественная подготовка скважины [УШГН] | AZ3: А2 — АСПО | BA3: КР1-2 — Отключение отдельных пластов. | BB3: Абразивный износ | BC3: Абразивный износ | BD3: Абразивный износ | BE3: Абразивный износ | BF3: Дефектовочная ведомость | BG3: Вероятная причина | BH3: Низкая | BI3: Удаление АСПО углеводородным растворителем | BJ3: ШГН — 32 мм | BK3: ЭЦН — габарит 5У | BM3: ШГН — серия НВ1С-32 | BN3: ЭЦН — серия УЭЦН-5У | BO3: ЭВН 5-16-1500 | BQ3: После ремонта | BR3: НКТ с высаженными концами | BS3: Подъём | BT3: 32 мм | BZ3: Отсутствие подачи | CA3: Отсутствие подачи | CB3: Рабочие органы насоса | CC3: Рабочие органы насоса | CD3: Абразивный износ | CE3: Абразивный износ | CF3: ШГН — 32 мм | CG3: ШГН — серия НВ1С-32 | CH3: Отсутствие подачи | CI3: Рабочие органы насоса | CJ3: 1.2 — Нарушение глубины спуска [УЭЦН] | CK3: Абразивный износ | CL3: Борец | CM3: ПЭД — габарит 103 мм | CN3: КПпБП-120 3×13,3 | CO3: КПпБП-120 3×16 (удлинитель) | CP3: Борец | CQ3: Модульная гидрозащита — 81 мм | CR3: =IFERROR(INDEX('История отказов'!$AY$5:$AY$1204,SMALL($DK$2:$DK$1201,ROWS($CR$3:CR3))),"") | CS3: ТМСВ-Новомет | CT3: =IFERROR(INDEX('История отказов'!$AE$5:$AE$1204,SMALL($DC$2:$DC$1201,ROWS($CT$3:CT3))),"") | CU3: Борец | CV3: Борец | CW3: =IFERROR(INDEX('История отказов'!$AE$5:$AE$1204,SMALL($DG$2:$DG$1201,ROWS($CW$3:CW3))),"") | CX3: =IFERROR(INDEX('История отказов'!$AE$5:$AE$1204,SMALL($DF$2:$DF$1201,ROWS($CX$3:CX3))),"") | CY3: Новомет | CZ3: НКТ гладкая 73×5,5 мм | DA3: 2034 | DB3: =IF('История отказов'!AH6="","",'История отказов'!AH6) | DC3: =IF('История отказов'!AE6="","",IF(AND(COUNTIF($CT$2:$CT$2,'История отказов'!AE6)=0,COUNTIFS('История отказов'!$F$5:F6,"ШГН",'История отказов'!$AE$5:AE6,'История отказов'!AE6)=1,'История отказов'!F6="ШГН"),2,"")) | DD3: =IF('История отказов'!AE6="","",IF(AND(COUNTIF($CU$2:$CU$3,'История отказов'!AE6)=0,COUNTIFS('История отказов'!$F$5:F6,"ЭЦН",'История отказов'!$AE$5:AE6,'История отказов'!AE6)=1,'История отказов'!F6="ЭЦН"),2,"")) | DE3: =IF('История отказов'!AE6="","",IF(AND(COUNTIF($CV$2:$CV$3,'История отказов'!AE6)=0,COUNTIFS('История отказов'!$F$5:F6,"ЭВН",'История отказов'!$AE$5:AE6,'История отказов'!AE6)=1,'История отказов'!F6="ЭВН"),2,"")) | DF3: =IF('История отказов'!AE6="","",IF(AND(COUNTIF($CX$2:$CX$2,'История отказов'!AE6)=0,COUNTIFS('История отказов'!$F$5:F6,"ШВН",'История отказов'!$AE$5:AE6,'История отказов'!AE6)=1,'История отказов'!F6="ШВН"),2,"")) | DG3: =IF('История отказов'!AE6="","",IF(AND(COUNTIF($CW$2:$CW$2,'История отказов'!AE6)=0,COUNTIFS('История отказов'!$F$5:F6,"НПУ-ВД",'История отказов'!$AE$5:AE6,'История отказов'!AE6)=1,'История отказов'!F6="НПУ-ВД"),2,"")) | DH3: =IF('История отказов'!AE6="","",IF(AND(COUNTIF($CY$2:$CY$6,'История отказов'!AE6)=0,COUNTIF('История отказов'!$AE$5:AE6,'История отказов'!AE6)=1),2,"")) | DI3: =IF('История отказов'!AK6="","",IF(AND(COUNTIF($CL$2:$CL$3,'История отказов'!AK6)=0,COUNTIF('История отказов'!$AK$5:AK6,'История отказов'!AK6)=1),2,"")) | DJ3: =IF('История отказов'!AU6="","",IF(AND(COUNTIF($CP$2:$CP$3,'История отказов'!AU6)=0,COUNTIF('История отказов'!$AU$5:AU6,'История отказов'!AU6)=1),2,"")) | DK3: =IF('История отказов'!AY6="","",IF(AND(COUNTIF($CR$2:$CR$2,'История отказов'!AY6)=0,COUNTIF('История отказов'!$AY$5:AY6,'История отказов'!AY6)=1),2,"")) | DL3: =IF(DB3="","",IF(AND(COUNTIF($DA$2:$DA$47,DB3)=0,COUNTIF($DB$2:DB3,DB3)=1),2,""))
